Workbook

Sheet 지침
B2: 산업전환부문 정보비공개 신청 평가 참고 지침

Sheet 검토기준
B2: 산업전환부문 정보비공개 신청 검토 기준
B49: 1차 검토 결과_20220602(첫 통보일)
B50: 구분 | C50: 국내평가 | D50: 국내인증 | E50: 국외평가 | F50: 국외인증 | G50: 합계 | H50: 신청 사유 | K50: 검토결과 | M50: 이슈 사항
B51: 내부방침 | C51: 34 | D51: 86 | E51: 9 | F51: 69 | G51: =SUM(C51:F51) -> 198 | H51: 회사 내규, 내부 방침 등 | K51: 보완요청 필요 | M51: 국외사업 : 비공개 신청 건 심의중 처리되지 않고, 정보 확인 가능 > ORS 문의 필요 > 해결(신청사업은 심의중 처리, 차수별 구분)
B52: 개인정보보호 | C52: 3 | D52: 6 | E52: 0 | F52: 0 | G52: =SUM(C52:F52) -> 9 | H52: 사업자 개인정보 | K52: 보완요청 필요 | M52: 국내CDM 사업 중 동 사업을 여러 사업자가 신청한 경우 : 신청한 사업자에 한하여 심의중 처리(한화 울산소재 질산공장, 시화호)
B53: 업체정보보호 | C53: 10 | D53: 3 | E53: 1 | F53: 0 | G53: =SUM(C53:F53) -> 14 | H53: 업무상 비밀 보호 시설 운영 실적 포함 원주시 내부 정보 포함 생산 공정 등 외부 유출에 민감한 자료 포함 보안이 필요한 생산시설 배치도와 기타 생산설비 사진 질산공정 영업 비밀 내용이 반영 발전소 설비 및 관리 세부 정보 PoA 9181 CPA19-30 사업계획서 영업기밀사항등이 포함(사업비용 조달 방법) > 보완요청 후 재확인 필요(클리어스카이파트너스) | K53: 보완요청 필요 | M53: 인증 비공개 신청 : 모니터링 차수 중 하나만 신청하더라도 심의중 처리 (카프로 N2O, 휴캠스 질산공장) > 해결(차수에 따라 구분됨)
B54: 기타 | C54: 1 | D54: 0 | E54: 0 | F54: 0 | G54: =SUM(C54:F54) -> 1 | H54: 배출권에 대한 수익 배분 및 기타 세부 내용 | K54: 확인 필요
C55: =SUM(C51:C54) -> 48 | D55: =SUM(D51:D54) -> 95 | E55: =SUM(E51:E54) -> 10 | F55: =SUM(F51:F54) -> 69 | G55: =SUM(G51:G54) -> 222
B58: 2차 검토 결과_20221013(47차 인증위 통보 반영)
B59: 구분 | C59: 국내평가 | D59: 국내인증 | E59: 국외평가 | F59: 국외인증 | G59: 합계 | H59: 신청 사유 | K59: 검토결과
B60: 내부방침 | C60: 0 | D60: 11 | E60: 0 | F60: 1 | G60: =SUM(C60:F60) -> 12 | H60: 회사 내규, 내부 방침 등 | K60: 보완요청 필요
B61: 개인정보보호 | C61: 0 | D61: 1 | E61: 0 | F61: 0 | G61: =SUM(C61:F61) -> 1 | H61: 사업자 개인정보 | K61: 보완요청 필요
B62: 업체정보보호 | C62: 0 | D62: 0 | E62: 11 | F62: 0 | G62: =SUM(C62:F62) -> 11 | H62: PoA 9181 CPA19-30 사업계획서 영업기밀사항등이 포함(사업비용 조달 방법) > 보완요청 후 재확인 필요(클리어스카이파트너스) | K62: 보완요청 필요(증빙자료는 정보공개 대상 아님)
B63: 기타 | D63: 0 | E63: 0 | F63: 0 | G63: =SUM(C63:F63) -> 0
C64: =SUM(C60:C63) -> 0 | D64: =SUM(D60:D63) -> 12 | E64: =SUM(E60:E63) -> 11 | F64: =SUM(F60:F63) -> 1 | G64: =SUM(G60:G63) -> 24
B66: 변경 사항(6월 2일 대비 10월 13일)
B67: 평가(국내평가 +0) : 신규 승인 0건(신규 비공개 신청 1건)
B68: 평가(국외평가 +11) : 신규 승인 11건 추가
B69: 인증(국내인증 +12) : 신규 승인 12건 추가(신규 비공개 신청 5건)
B70: 인증(국외인증 +1) : 신규 승인 1건 추가
B72: 3차 검토 결과_20221130
B73: 구분 | C73: 국내평가 | D73: 국내인증 | E73: 국외평가 | F73: 국외인증 | G73: 합계 | H73: 신청 사유 | K73: 검토결과
B74: 내부방침 | C74: 1 | D74: 0 | E74: 0 | F74: 0 | G74: =SUM(C74:F74) -> 1 | H74: 회사 내규, 내부 방침 등 | K74: 보완요청 필요
B75: 개인정보보호 | C75: 0 | D75: 0 | E75: 0 | F75: 0 | G75: =SUM(C75:F75) -> 0 | H75: 사업자 개인정보 | K75: 보완요청 필요
B76: 업체정보보호 | C76: 1 | D76: 0 | E76: 0 | F76: 0 | G76: =SUM(C76:F76) -> 1 | H76: 업체정보보호(업무상 비밀) | K76: 보완요청 필요
B77: 기타 | C77: 0 | D77: 0 | E77: 0 | F77: 0 | G77: =SUM(C77:F77) -> 0
C78: =SUM(C74:C77) -> 2 | D78: =SUM(D74:D77) -> 0 | E78: =SUM(E74:E77) -> 0 | F78: =SUM(F74:F77) -> 0 | G78: =SUM(G74:G77) -> 2
B80: 변경 사항(10월 13일 대비 11월 30일)
B81: 평가(국내평가 +2) : 신규 승인 2건 추가(신규 비공개 신청 0건)
B84: 4차 검토 결과_20230419
B85: 구분 | C85: 국내평가 | D85: 국내인증 | E85: 국외평가 | F85: 국외인증 | G85: 합계 | H85: 신청 사유 | K85: 검토결과
B86: 내부방침 | C86: 1 | D86: 5 | E86: 0 | F86: 0 | G86: =SUM(C86:F86) -> 6 | H86: 회사 내규, 내부 방침 등 | K86: 보완요청 필요
B87: 개인정보보호 | C87: 0 | D87: 0 | E87: 0 | F87: 0 | G87: =SUM(C87:F87) -> 0 | H87: 사업자 개인정보 | K87: 보완요청 필요
B88: 업체정보보호 | C88: 1 | D88: 0 | E88: 3 | F88: 0 | G88: =SUM(C88:F88) -> 4 | H88: 업체정보보호(업무상 비밀) | K88: 보완요청 필요
B89: 기타 | C89: 0 | D89: 0 | E89: 0 | F89: 0 | G89: =SUM(C89:F89) -> 0
C90: =SUM(C86:C89) -> 2 | D90: =SUM(D86:D89) -> 5 | E90: =SUM(E86:E89) -> 3 | F90: =SUM(F86:F89) -> 0 | G90: =SUM(G86:G89) -> 10
B92: 변경 사항(11월 30일 대비 03월 27일)
B93: 평가(국내평가 +2) : 신규 승인 1건 추가(신규 비공개 신청 1건)
B94: 평가(국외평가 +3) : 신규 승인 3건 추가(신규 비공개 신청 0건)
B95: 평가(국내인증 +5) : 신규 승인 0건 추가(신규 비공개 신청 5건)
...

Sheet 통계
B2: 산업전환부문 정보비공개 신청 평가 현황
B13: 2026.07.07
B14: 구분 | D14: 신청건수 | E14: 정보 비공개 신청 평가 종료 | H14: 평가중 | L14: 평가 불필요
E15: 승인 | F15: 반려 | G15: 소계 | H15: 사업자 | I15: 검토반 | K15: 소계 | L15: 사업 반려 | M15: 정보 비공개 신청 반려 | P15: 소계
H16: 의견 통보 | I16: 의견 보완 | J16: 신규 신청 | M16: 반려 완료 | N16: 사업자 요청 | O16: 보류(반려 필요)
B17: 평가 (정보비공개) | C17: 국내 | D17: =COUNT('(비공개)국내평가'!A:A) -> 106 | E17: =COUNTIF('(비공개)국내평가'!$Q:$Q,"*승인*") -> 6 | F17: =SUM(L17:O17) -> 59 | G17: =SUM(E17:F17) -> 65 | H17: =COUNTIFS('(비공개)국내평가'!Q:Q,"*보완요청*",'(비공개)국내평가'!R:R,"*사업자*") -> 39 | I17: =COUNTIFS('(비공개)국내평가'!Q:Q,"*보완완료*",'(비공개)국내평가'!R:R,"*검토반*") -> 1 | J17: =COUNTIFS('(비공개)국내평가'!Q:Q,"*평가필요*",'(비공개)국내평가'!R:R,"*검토반*") -> 1 | K17: =SUM(H17:J17) -> 41 | L17: =COUNTIF('(비공개)국내평가'!$K:$K,"*반려*")-COUNTIFS('(비공개)국내평가'!K:K,"*반려*",'(비공개)국내평가'!L:L,"사업변경 신청")-COUNTIFS('(비공개)국내평가'!K:K,"*반려*",'(비공개)국내평가'!L:L,"인증유효기간 갱신") -> 39 | M17: =COUNTIFS('(비공개)국내평가'!$Q:$Q,"*반려완료*",'(비공개)국내평가'!R:R,"*종결*") -> 20 | N17: =COUNTIFS('(비공개)국내평가'!$Q:$Q,"*반려요청*",'(비공개)국내평가'!$R:$R,"*검토반*") -> 0 | O17: =COUNTIFS('(비공개)국내평가'!$Q:$Q,"*보류*",'(비공개)국내평가'!$R:$R,"*반려필요*") -> 0 | P17: =SUM(L17:O17) -> 59
C18: 국외 | D18: =COUNT('(비공개)국외평가'!A:A) -> 24 | E18: =COUNTIF('(비공개)국외평가'!$Q:$Q,"*승인*") -> 0 | F18: =SUM(L18:O18) -> 9 | G18: =SUM(E18:F18) -> 9 | H18: =COUNTIFS('(비공개)국외평가'!Q:Q,"*보완요청*",'(비공개)국외평가'!R:R,"*사업자*") -> 15 | I18: =COUNTIFS('(비공개)국외평가'!Q:Q,"*보완완료*",'(비공개)국외평가'!R:R,"*검토반*") -> 0 | J18: =COUNTIFS('(비공개)국외평가'!Q:Q,"*평가필요*",'(비공개)국외평가'!R:R,"*검토반*") -> 0 | K18: =SUM(H18:J18) -> 15 | L18: =COUNTIF('(비공개)국외평가'!$K:$K,"*반려*")-COUNTIFS('(비공개)국외평가'!K:K,"*반려*",'(비공개)국외평가'!L:L,"사업변경 신청")-COUNTIFS('(비공개)국외평가'!K:K,"*반려*",'(비공개)국외평가'!L:L,"인증유효기간 갱신") -> 0 | M18: =COUNTIFS('(비공개)국외평가'!$Q:$Q,"*반려완료*",'(비공개)국외평가'!R:R,"*종결*") -> 9 | N18: =COUNTIFS('(비공개)국외평가'!$Q:$Q,"*반려요청*",'(비공개)국외평가'!$R:$R,"*검토반*") -> 0 | O18: =COUNTIFS('(비공개)국외평가'!$Q:$Q,"*보류*",'(비공개)국외평가'!$R:$R,"*반려필요*") -> 0 | P18: =SUM(L18:O18) -> 9
B19: 인증 (정보비공개) | C19: 국내 | D19: =COUNT('(비공개)국내인증'!B:B) -> 126 | E19: =COUNTIF('(비공개)국내인증'!$S:$S,"*승인*") -> 2 | F19: =SUM(L19:O19) -> 19 | G19: =SUM(E19:F19) -> 21 | H19: =COUNTIFS('(비공개)국내인증'!S:S,"*보완요청*",'(비공개)국내인증'!T:T,"*사업자*") -> 105 | I19: =COUNTIFS('(비공개)국내인증'!S:S,"*보완완료*",'(비공개)국내인증'!T:T,"*검토반*") -> 0 | J19: =COUNTIFS('(비공개)국내인증'!S:S,"*평가필요*",'(비공개)국내인증'!T:T,"*검토반*") -> 0 | K19: =SUM(H19:J19) -> 105 | L19: =COUNTIFS('(비공개)국내인증'!S:S,"*선택*",'(비공개)국내인증'!T:T,"종결") -> 1 | M19: =COUNTIFS('(비공개)국내인증'!$S:$S,"*반려완료*",'(비공개)국내인증'!T:T,"*종결*") -> 4 | N19: =COUNTIFS('(비공개)국내인증'!S:S,"*반려요청*",'(비공개)국내인증'!T:T,"*검토반*") -> 14 | O19: =COUNTIFS('(비공개)국내인증'!S:S,"*보류*",'(비공개)국내인증'!T:T,"*반려필요*") -> 0 | P19: =SUM(L19:O19) -> 19
C20: 국외 | D20: =COUNT('(비공개)국외인증'!B:B) -> 75 | E20: =COUNTIF('(비공개)국외인증'!$U:$U,"*승인*") -> 0 | F20: =SUM(L20:O20) -> 74 | G20: =SUM(E20:F20) -> 74 | H20: =COUNTIFS('(비공개)국외인증'!U:U,"*보완요청*",'(비공개)국외인증'!V:V,"*사업자*") -> 1 | I20: =COUNTIFS('(비공개)국외인증'!U:U,"*보완완료*",'(비공개)국외인증'!V:V,"*검토반*") -> 0 | J20: =COUNTIFS('(비공개)국외인증'!U:U,"*평가필요*",'(비공개)국외인증'!V:V,"*검토반*") -> 0 | K20: =SUM(H20:J20) -> 1 | L20: =COUNTIF('(비공개)국외인증'!$P:$P,"*반려*") -> 5 | M20: =COUNTIFS('(비공개)국외인증'!$U:$U,"*반려완료*",'(비공개)국외인증'!V:V,"*종결*") -> 69 | N20: =COUNTIFS('(비공개)국외인증'!U:U,"*반려요청*",'(비공개)국외인증'!V:V,"*검토반*") -> 0 | O20: =COUNTIFS('(비공개)국외인증'!U:U,"*보류*",'(비공개)국외인증'!V:V,"*반려필요*") -> 0 | P20: =SUM(L20:O20) -> 74
B21: 합계 | D21: =SUM(D17:D20) -> 331 | E21: =SUM(E17:E20) -> 8 | F21: =SUM(F17:F20) -> 161 | G21: =SUM(G17:G20) -> 169 | H21: =SUM(H17:H20) -> 160 | I21: =SUM(I17:I20) -> 1 | J21: =SUM(J17:J20) -> 1 | K21: =SUM(K17:K20) -> 162 | ... P21: =SUM(P17:P20) -> 161
D22: 신청 건수: 평가종료 소계 + 평가중 소계 | H22: 의견통보: 사업자에게 정보비공개 신청 검토 의견 통보 | L22: 사업 반려: 정보비공개 신청하였으나, 외부사업이 평가/인증 단계에서 반려
H23: 의견 보완: 검토 의견 보완 후 재신청 | L23: 반려 완료: 사업자 요청에 의한 반려 완료
H24: 신규 신청: 정보비공개 신청되어 평가 필요 | L24: 사업자 요청: 사업자가 정보 비공개 신청 철회하여 반려 요청
L25: 보류: 평가가 불필요해진 사업
B26: 2026.06.16
B27: 구분 | D27: 신청건수 | E27: 정보 비공개 신청 평가 종료 | H27: 평가중 | L27: 평가 불필요
E28: 승인 | F28: 반려 | G28: 소계 | H28: 사업자 | I28: 검토반 | K28: 소계 | L28: 사업 반려 | M28: 정보 비공개 신청 반려 | P28: 소계
H29: 의견 통보 | I29: 의견 보완 | J29: 신규 신청 | M29: 완료 | N29: 사업자 요청 | O29: 보류(반려 필요)
B30: 평가 (정보비공개) | C30: 국내 | D30: 106 | E30: 6 | F30: 59 | G30: 65 | H30: 39 | I30: 1 | J30: 1 | K30: 41 | L30: 39 | M30: 20 | N30: 0 | O30: 0 | P30: 59
C31: 국외 | D31: 24 | E31: 0 | F31: 9 | G31: 9 | H31: 15 | I31: 0 | J31: 0 | K31: 15 | L31: 0 | M31: 9 | N31: 0 | O31: 0 | P31: 9
B32: 인증 (정보비공개) | C32: 국내 | D32: 126 | E32: 2 | F32: 19 | G32: 21 | H32: 105 | I32: 0 | J32: 0 | K32: 105 | L32: 1 | M32: 4 | N32: 14 | O32: 0 | P32: 19
C33: 국외 | D33: 75 | E33: 0 | F33: 74 | G33: 74 | H33: 1 | I33: 0 | J33: 0 | K33: 1 | L33: 5 | M33: 69 | N33: 0 | O33: 0 | P33: 74
B34: 합계 | D34: 331 | E34: 8 | F34: 161 | G34: 169 | H34: 160 | I34: 1 | J34: 1 | K34: 162 | L34: 45 | M34: 102 | N34: 14 | O34: 0 | P34: 161
D35: =D17-D30 -> 0 | E35: =E17-E30 -> 0 | F35: =F17-F30 -> 0 | G35: =G17-G30 -> 0 | H35: =H17-H30 -> 0 | I35: =I17-I30 -> 0 | J35: =J17-J30 -> 0 | K35: =K17-K30 -> 0 | ... P35: =P17-P30 -> 0
D36: =D18-D31 -> 0 | E36: =E18-E31 -> 0 | F36: =F18-F31 -> 0 | G36: =G18-G31 -> 0 | H36: =H18-H31 -> 0 | I36: =I18-I31 -> 0 | J36: =J18-J31 -> 0 | K36: =K18-K31 -> 0 | ... P36: =P18-P31 -> 0
D37: =D19-D32 -> 0 | E37: =E19-E32 -> 0 | F37: =F19-F32 -> 0 | G37: =G19-G32 -> 0 | H37: =H19-H32 -> 0 | I37: =I19-I32 -> 0 | J37: =J19-J32 -> 0 | K37: =K19-K32 -> 0 | ... P37: =P19-P32 -> 0
D38: =D20-D33 -> 0 | E38: =E20-E33 -> 0 | F38: =F20-F33 -> 0 | G38: =G20-G33 -> 0 | H38: =H20-H33 -> 0 | I38: =I20-I33 -> 0 | J38: =J20-J33 -> 0 | K38: =K20-K33 -> 0 | ... P38: =P20-P33 -> 0
B40: 2024.11.15
B41: 구분 | D41: 신청건수 | E41: 정보 비공개 평가 완료 | H41: 사업 승인 전 | I41: 평가중
E42: 승인 | F42: 반려 | G42: 소계 | I42: 사업 승인 후(정보비공개 평가대상) | M42: 반려 사업 | N42: 소계 (보완/평가중)
I43: 기 평가 완료 (승인 건 제외) | J43: 추가 평가 대상 | K43: 반려 완료
L44: 반려 요청
B45: 평가 (정보비공개) | C45: 국내 | D45: 100 | E45: 2 | F45: 39 | G45: 41 | H45: 6 | I45: 53 | J45: 0 | K45: 1 | L45: 0 | M45: 38 | N45: 52 | O45: 사업 승인 전에 씨큐브 제외, 기 평가 완료에 씨큐브 포함(향후 승인 건수(2건)에 추가될 예정)
C46: 국외 | D46: 24 | E46: 0 | F46: 9 | G46: 9 | H46: 0 | I46: 24 | J46: 0 | K46: 9 | L46: 0 | M46: 0 | N46: 15
B47: 인증 (정보비공개) | C47: 국내 | D47: 126 | E47: 1 | F47: 5 | G47: 6 | H47: 4 | I47: 116 | J47: 0 | K47: 4 | L47: 0 | M47: 1 | N47: 112
C48: 국외 | D48: 75 | E48: 0 | F48: 74 | G48: 74 | H48: 0 | I48: 70 | J48: 0 | K48: 69 | L48: 0 | M48: 5 | N48: 1
B49: 합계 | D49: 325 | E49: 3 | F49: 127 | G49: 130 | H49: 10 | I49: 263 | J49: 0 | K49: 83 | L49: 0 | M49: 44 | N49: 180
B50: * 정보비공개 DB : 2024-06-10 | H50: 사업 승인 전 : 정보비공개 신청했으나, 사업 승인 전 단계
H51: 기 평가 완료 : 신청 사유 평가 후 내용 통보(최종 승인건수 제외)
H52: 추가 평가 대상 : 보완 완료 또는 신규 사업 승인 건이며, 다음 버전에서 "기 평가 완료" 항목으로 이동
...

Sheet (비공개)국내평가
E1: 정보비공개 DB | I1: 국내평가 DB(참고용)
A2: 번호 | B2: 사업유형 | C2: 사업명 | D2: 업체명 | E2: 정보비공개 신청일 | F2: 관장기관 | G2: 처리일 | H2: 진행상태 | I2: 사업 신청일 | J2: 평가 가능 여부 | K2: 처리이력 | L2: 현재 상태 | M2: h | N2: 진행상태 | O2: 현 위치 | P2: 검토대상 | Q2: 진행상태 | R2: 현 위치 | S2: 업데이트 | T2: 담당자 | U2: 비고 | V2: 권리 | W2: 대외비 자료 | X2: 계약서류 | Y2: 연료 사용량 | Z2: 공정 도식도 | AA2: 영업비밀 | AB2: 내규방침 제출여부 | AC2: 비공개 신청사유 | AD2: 특이사항
A3: 1 | B3: 단일감축사업 | C3: 생태산업개발을 통한 미세먼지 및 온실가스 감축 사업-산단 친환경설비 인프라지원 | D3: (주)신우테크 | E3: =VLOOKUP(C3,'외부사업 비공개승인관리_국내'!$C:$H,4,FALSE) -> 2025-12-15 | F3: =VLOOKUP(C3,'외부사업 비공개승인관리_국내'!$C:$H,5,FALSE) -> 산업통상부 | G3: =VLOOKUP(C3,'외부사업 비공개승인관리_국내'!$C:$H,6,FALSE) -> 2026-01-15 | H3: =VLOOKUP(C3,'외부사업 비공개승인관리_국내'!$C:$H,3,FALSE) -> 보완요청 | I3: =LEFT(VLOOKUP(C3,'국내평가(ORS)'!P:AO,26,0),10) -> 2025-12-15 | J3: =IF(I3=E3,"O","X") -> O | K3: =VLOOKUP(C3, '국내평가(ORS)'!P:AL, 23, 0) -> 평가반려 2025-12-16 | L3: =VLOOKUP(C3, '국내평가(ORS)'!A:AL, 2, 0) -> 반려 | Q3: 반려요청 | R3: 사업자 | S3: 46056 | T3: 에코시안 | U3: 해당 사업이 반려(사업자 요청)되었으므로 철회하도록 통보(26.1.14)
A4: 2 | B4: 묶음감축사업 | C4: 서울시 20212023년 LED 도로조명 교체를 통한 온실가스 감축사업 | D4: 서울특별시 | E4: =VLOOKUP(C4,'외부사업 비공개승인관리_국내'!$C:$H,4,FALSE) -> 2025-11-04 | F4: =VLOOKUP(C4,'외부사업 비공개승인관리_국내'!$C:$H,5,FALSE) -> 산업통상부 | G4: =VLOOKUP(C4,'외부사업 비공개승인관리_국내'!$C:$H,6,FALSE) -> 2026-01-22 | H4: =VLOOKUP(C4,'외부사업 비공개승인관리_국내'!$C:$H,3,FALSE) -> 보완요청 | I4: =LEFT(VLOOKUP(C4,'국내평가(ORS)'!P:AO,26,0),10) -> 2025-11-04 | J4: =IF(I4=E4,"O","X") -> O | K4: =VLOOKUP(C4, '국내평가(ORS)'!P:AL, 23, 0) -> [보완3차]신청 2026-09-08 (9일째) | L4: =VLOOKUP(C4, '국내평가(ORS)'!A:AL, 2, 0) -> 보완3차_검토중 | Q4: 보완요청 | R4: 사업자 | S4: 46044 | T4: KECM | U4: (1차) 「명세서 공개 심사위원회 구성 및 운영에 관한 규정」 [별표1]에 따라 비공개 신청사유를 하기와 같이 보완 요청 드립니다. - 사업계획서(모니터링보고서) 내용 중 보안유지 필요 부분, 위치 및 사유 구체화(증빙자료는 정보공개 대상 아님) - 필요 시 정보 비공개사유에 대한 증빙자료(회사 내규, 계약서, 설비 관련 자료 등)를 제출 요청 단, 투명성 원칙에 따라 민감사항이 사업계획서 및 모니터링보고서, 검증 보고서 내 문서에 포함되지 않아도 되는 경우(필수 작성 항목이 아닌 경우) 해당사항은 증빙자료로만 제출하고 본 비공개신청 건은 철회 신청해주시기 바랍니다. | AC4: 업체정보보호(내부 정보) | AD4: (1차 통보) 2026.1.22
A5: 3 | B5: 단일감축사업 | C5: 명광아스콘의 B-C유에서 LPG로 연료전환을 통한 온실가스 감축 외부사업 | D5: (주)삼천리 | E5: =VLOOKUP(C5,'외부사업 비공개승인관리_국내'!$C:$H,4,FALSE) -> 2025-01-21 | F5: =VLOOKUP(C5,'외부사업 비공개승인관리_국내'!$C:$H,5,FALSE) -> 산업통상부 | G5: =VLOOKUP(C5,'외부사업 비공개승인관리_국내'!$C:$H,6,FALSE) -> 2025-09-08 | H5: =VLOOKUP(C5,'외부사업 비공개승인관리_국내'!$C:$H,3,FALSE) -> 심의완료 | I5: =LEFT(VLOOKUP(C5,'국내평가(ORS)'!P:AO,26,0),10) -> 2025-01-21 | J5: =IF(I5=E5,"O","X") -> O | K5: =VLOOKUP(C5, '국내평가(ORS)'!P:AL, 23, 0) -> [보완3차]착수신고 2026-01-29 | L5: =VLOOKUP(C5, '국내평가(ORS)'!A:AL, 2, 0) -> 승인 | Q5: 심의승인 | R5: 종결 | S5: 45916 | T5: KECM | U5: 기업 경영에 관련된 정보 외부유출 방지 : 사업장 설비 현황, 연료사용량은 기업 경영에 중요한 정보로써 타 업체로의 정보유출 방지 필요 - 설비 현황 (사업계획서 12-14p, 34p) - 연료 사용량 (사업계획서 22-29p)
A6: 4 | B6: 묶음감축사업 | C6: (주)전유산업 외 2개사의 고효율 공기압축기 교체를 통한 온실가스 감축사업 | D6: 에스피앤지주식회사 | E6: =VLOOKUP(C6,'외부사업 비공개승인관리_국내'!$C:$H,4,FALSE) -> 2025-04-21 | F6: =VLOOKUP(C6,'외부사업 비공개승인관리_국내'!$C:$H,5,FALSE) -> 산업통상부 | G6: =VLOOKUP(C6,'외부사업 비공개승인관리_국내'!$C:$H,6,FALSE) -> 2025-05-07 | H6: =VLOOKUP(C6,'외부사업 비공개승인관리_국내'!$C:$H,3,FALSE) -> 반려 | I6: =LEFT(VLOOKUP(C6,'국내평가(ORS)'!P:AO,26,0),10) -> 2022-10-07 | J6: =IF(I6=E6,"O","X") -> X | K6: =VLOOKUP(C6, '국내평가(ORS)'!P:AL, 23, 0) -> [보완3차]착수신고 2026-09-09 | L6: =VLOOKUP(C6, '국내평가(ORS)'!A:AL, 2, 0) -> 승인 | P6: =IF(AND(H6<>"반려", L6<>"반려"),"검토가능","") | Q6: 반려완료 | R6: 종결 | S6: 45833 | T6: KECM | U6: 사업자 반려 요청
A7: 5 | B7: 단일감축사업 | C7: 부산경남우유협동조합 울산공장의 B-C유에서 LPG로 연료전환을 통한 온실가스 감축 외부사업 | D7: (주)삼천리 | E7: =VLOOKUP(C7,'외부사업 비공개승인관리_국내'!$C:$H,4,FALSE) -> 2025-01-07 | F7: =VLOOKUP(C7,'외부사업 비공개승인관리_국내'!$C:$H,5,FALSE) -> 산업통상부 | G7: =VLOOKUP(C7,'외부사업 비공개승인관리_국내'!$C:$H,6,FALSE) -> 2025-09-08 | H7: =VLOOKUP(C7,'외부사업 비공개승인관리_국내'!$C:$H,3,FALSE) -> 심의완료 | I7: =LEFT(VLOOKUP(C7,'국내평가(ORS)'!P:AO,26,0),10) -> 2025-01-07 | J7: =IF(I7=E7,"O","X") -> O | K7: =VLOOKUP(C7, '국내평가(ORS)'!P:AL, 23, 0) -> [보완1차]착수신고 2026-01-29 | L7: =VLOOKUP(C7, '국내평가(ORS)'!A:AL, 2, 0) -> 승인 | Q7: 심의승인 | R7: 종결 | S7: 45916 | T7: 에코시안_남혜원
A8: 6 | B8: 단일감축사업 | C8: 엑시콘 태양광 발전설비 설치 및 자가사용을 통한 온실가스 감축사업 | D8: (주)엑시콘 천안지점 | E8: =VLOOKUP(C8,'외부사업 비공개승인관리_국내'!$C:$H,4,FALSE) -> 2026-05-19 | F8: =VLOOKUP(C8,'외부사업 비공개승인관리_국내'!$C:$H,5,FALSE) -> 기후에너지환경부 | G8: =VLOOKUP(C8,'외부사업 비공개승인관리_국내'!$C:$H,6,FALSE) -> 2026-05-20 | H8: =VLOOKUP(C8,'외부사업 비공개승인관리_국내'!$C:$H,3,FALSE) -> 반려 | I8: =LEFT(VLOOKUP(C8,'국내평가(ORS)'!P:AO,26,0),10) -> 2024-11-18 | J8: =IF(I8=E8,"O","X") -> X | K8: =VLOOKUP(C8, '국내평가(ORS)'!P:AL, 23, 0) -> [보완3차]심의승인 2026-09-08 | L8: =VLOOKUP(C8, '국내평가(ORS)'!A:AL, 2, 0) -> 승인 | P8: =IF(AND(H8<>"반려", L8<>"반려"),"검토가능","") | Q8: 반려완료 | R8: 종결 | S8: 46168 | T8: 에코시안_조은지 | U8: ※ 사업자 요청으로 반려 처리 <신청사유> 기업 경영에 관련된 정보 외부유출 방지 - 사업장 설비 현황, 연료사용량은 기업 경영에 중요한 정보로써 타 업체로의 정보유출 방지 필요 - 설비 현황 (사업계획서 13페이지), 재생에너지 발전설비를 통해 자가 사용된 순 전력량 (사업계획서 20페이지) <1차 통보> ∙ 「명세서 공개 심사위원회 구성 및 운영에 관한 규정」 [별표1]에 따라 비공개 신청사유를 하기와 같이 보완 요청 드립니다. - 사업계획서 내용 중 보안유지 필요 사유 구체화 필요(증빙자료는 정보공개 대상 아님) - 필요 시 정보 비공개사유에 대한 증빙자료 제출 필요하며, 신청사유와 관련된 자료로 첨부(회사 내규, 계약서, 설비 관련 자료 등) ∙ 단, 투명성 원칙에 따라 민감사항이 사업계획서 내 문서에 포함되지 않아도 되는 경우(필수 작성 항목이 아닌 경우) 해당 사항은 증빙자료로만 제출하고 본 비공개 신청건은 철회 신청해주시기 바랍니다. | AC8: 업체정보보호(내부 정보)
A9: 7 | B9: 묶음감축사업 | C9: 주택용 태양광 발전 시스템을 이용한 자가사용 묶음 감축사업 | D9: (주)후시파트너스 | E9: =VLOOKUP(C9,'외부사업 비공개승인관리_국내'!$C:$H,4,FALSE) -> 2024-10-16 | F9: =VLOOKUP(C9,'외부사업 비공개승인관리_국내'!$C:$H,5,FALSE) -> 기후에너지환경부 | G9: =VLOOKUP(C9,'외부사업 비공개승인관리_국내'!$C:$H,6,FALSE) -> 2025-01-09 | H9: =VLOOKUP(C9,'외부사업 비공개승인관리_국내'!$C:$H,3,FALSE) -> 보완요청 | I9: =LEFT(VLOOKUP(C9,'국내평가(ORS)'!P:AO,26,0),10) -> 2024-10-16 | J9: =IF(I9=E9,"O","X") -> O | K9: =VLOOKUP(C9, '국내평가(ORS)'!P:AL, 23, 0) -> 평가반려 2026-07-27 | L9: =VLOOKUP(C9, '국내평가(ORS)'!A:AL, 2, 0) -> 반려 | M9: 승인 전 | N9: 선택 | O9: 선택 | P9: =IF(AND(H9<>"반려", L9<>"반려"),"검토가능","") | Q9: 보완요청 | R9: 사업자 | S9: 45611 | T9: 에코시안_조영우 | U9: 제출서류 미비로 보완 요청. 보완 요청 통보 문구 기재(공단 통보)
A10: 8 | B10: 묶음감축사업 | C10: 2015년 춘천시 도로조명 LED 교체를 통한 묶음 감축사업 | D10: 춘천시 | E10: =VLOOKUP(C10,'외부사업 비공개승인관리_국내'!$C:$H,4,FALSE) -> 2024-07-03 | F10: =VLOOKUP(C10,'외부사업 비공개승인관리_국내'!$C:$H,5,FALSE) -> 산업통상부 | G10: =VLOOKUP(C10,'외부사업 비공개승인관리_국내'!$C:$H,6,FALSE) -> 2025-06-12 | H10: =VLOOKUP(C10,'외부사업 비공개승인관리_국내'!$C:$H,3,FALSE) -> 심의완료 | I10: =LEFT(VLOOKUP(C10,'국내평가(ORS)'!P:AO,26,0),10) -> 2018-01-03 | J10: =IF(I10=E10,"O","X") -> X | K10: =VLOOKUP(C10, '국내평가(ORS)'!P:AL, 23, 0) -> [보완3차]착수신고 2021-09-30 | L10: =VLOOKUP(C10, '국내평가(ORS)'!A:AL, 2, 0) -> 승인 | M10: 검토필요 | N10: 보완요청 | O10: 사업자 | Q10: 심의승인 | R10: 종결 | S10: 45833 | T10: 에코시안_조영우 | U10: 심의 승인 | AC10: 업체정보보호(내부 정보)
A11: 9 | B11: 묶음감축사업 | C11: 2022년 춘천시 도로조명 LED 교체를 통한 감축사업 | D11: 춘천시 | E11: =VLOOKUP(C11,'외부사업 비공개승인관리_국내'!$C:$H,4,FALSE) -> 2025-10-28 | F11: =VLOOKUP(C11,'외부사업 비공개승인관리_국내'!$C:$H,5,FALSE) -> 산업통상부 | G11: =VLOOKUP(C11,'외부사업 비공개승인관리_국내'!$C:$H,6,FALSE) -> 2025-04-28 | H11: =VLOOKUP(C11,'외부사업 비공개승인관리_국내'!$C:$H,3,FALSE) -> 보완완료 | I11: =LEFT(VLOOKUP(C11,'국내평가(ORS)'!P:AO,26,0),10) -> 2023-01-11 | J11: =IF(I11=E11,"O","X") -> X | K11: =VLOOKUP(C11, '국내평가(ORS)'!P:AL, 23, 0) -> [보완3차]문서재제출요청 2026-02-02 | L11: =VLOOKUP(C11, '국내평가(ORS)'!A:AL, 2, 0) -> 보완3차_문서보완중 | M11: 승인 전 | N11: 선택 | O11: 선택 | P11: =IF(AND(H11<>"반려", L11<>"반려"),"검토가능","") -> 검토가능 | Q11: 보완완료 | R11: 검토반 | S11: 45992 | T11: 에코시안 | U11: [1차 통보] ㅇ 「명세서 공개 심사위원회 구성 및 운영에 관한 규정」 [별표1]에 따라 비공개 신청사유를 하기와 같이 보완 요청 드립니다. - 사업계획서(모니터링보고서) 내용 중 보안유지 필요 부분, 위치 및 사유 구체화(증빙자료는 정보공개 대상 아님) - 필요 시 정보 비공개사유에 대한 증빙자료 제출 요청 ㅇ 단, 투명성 원칙에 따라 민감사항이 사업계획서 및 모니터링보고서, 검증 보고서 내 문서에 포함되지 않아도 되는 경우(필수 작성 항목이 아닌 경우) 해당사항은 증빙자료로만 제출하고 본 비공개신청건은 철회 신청해주시기 바랍니다. [1차 보완] 정보비공개 판단 기준은 &lsquo;온실가스배출량명세서 정보의 공개 및 비공개 신청 심사 기준&rsquo;을 준용하고 있는데, 이 규정은 법적으로 제출이 의무화된 온실가스배출관리업체, 할당대상업체의 명세서에 대한 규정임. 그에 비해 업체가 자발적으로 참여하고 제출하는 외부사업의 사업계획서의 비공개 심사에는 업체의 의견을 보다 존중해야 할 것으로 사료됨. 본 외부사업의 사업계획서 상 비공개를 희망하는 부분 및 그 사유를 다음과 같이 기술함. 1.2. 사업의 위치 (3) 사업의 주소, 보안등 번호, 전주번호 - 이 사업의 대상인 도로조명의 주소, 등번호, 전주번호는 중요한 정보이며, 그 목록 전체를 춘천시가 일반에게 공개할 의무는 없으며, 오남용될 가능성도 있어 춘천시는 이 정보의 공개를 원하지 않음 [근거: 공공기관의 정보공개에 관한 법률 제9조제1항제5호] 2. 베이스라인 및 모니터링 방법론, 3. 온실가스 감축량 산정, 4. 모니터링 계획 - 본 외부사업의 베이스라인 및 모니터링 방법, 온실가스 감축량 산정 방법, 모니터링 계획이 춘천시 고유의 특성을 반영하여 구체적으로 기술되어 있기 때문에 정보공개를 원하지 않음. 또한, 이 사업계획서를 작성하기 위하여 춘천시가 오랜 기간 동안 시간과 노력과 예산을 투자하여 작성한 연구성과물이기 때문에 무상으로 이를 일반인에게 공개하는 것은 공평하지 못하며, 시장질서에도 바람직하지 않다고 사료되므로 춘천시는 비공개를 요청함 [근거: 공공기관의 정보공개에 관한 법률 제9조제1항제5호,제7호] 6. 사업자 정보 - 사업자 담당자의 개인 정보 보호 차원에서 이 정보의 공개를 원하지 않음 [근거: 공공기관의 정보공개에 관한 법률 제9조제1항제6호] | AC11: 업체정보보호(내부 정보)
A12: 10 | B12: 묶음감축사업 | C12: 신성이앤에스 영덕군 태양광 발전시설의 리파워링 사업 | D12: 신성이앤에스 | E12: =VLOOKUP(C12,'외부사업 비공개승인관리_국내'!$C:$H,4,FALSE) -> 2024-01-29 | F12: =VLOOKUP(C12,'외부사업 비공개승인관리_국내'!$C:$H,5,FALSE) -> 기후에너지환경부 | G12: =VLOOKUP(C12,'외부사업 비공개승인관리_국내'!$C:$H,6,FALSE) -> 2025-01-09 | H12: =VLOOKUP(C12,'외부사업 비공개승인관리_국내'!$C:$H,3,FALSE) -> 보완요청 | I12: =LEFT(VLOOKUP(C12,'국내평가(ORS)'!P:AO,26,0),10) -> 2024-01-29 | J12: =IF(I12=E12,"O","X") -> O | K12: =VLOOKUP(C12, '국내평가(ORS)'!P:AL, 23, 0) -> [보완1차]보완요청 2024-03-11 | L12: =VLOOKUP(C12, '국내평가(ORS)'!A:AL, 2, 0) -> 보완1차_보완중 | M12: 승인 전 | N12: 선택 | O12: 선택 | P12: =IF(AND(H12<>"반려", L12<>"반려"),"검토가능","") -> 검토가능 | Q12: 보완요청 | R12: 사업자 | S12: 45380 | T12: KECM_조수민 | U12: 제출서류 미비로 보완 요청. 보완 요청 통보 문구 기재(공단 통보)
A13: 11 | B13: 묶음감축사업 | C13: 신성이앤에스 영동군 태양광 발전시설의 리파워링 사업 | D13: 신성이앤에스 | E13: =VLOOKUP(C13,'외부사업 비공개승인관리_국내'!$C:$H,4,FALSE) -> 2024-01-29 | F13: =VLOOKUP(C13,'외부사업 비공개승인관리_국내'!$C:$H,5,FALSE) -> 기후에너지환경부 | G13: =VLOOKUP(C13,'외부사업 비공개승인관리_국내'!$C:$H,6,FALSE) -> 2025-01-09 | H13: =VLOOKUP(C13,'외부사업 비공개승인관리_국내'!$C:$H,3,FALSE) -> 보완요청 | I13: =LEFT(VLOOKUP(C13,'국내평가(ORS)'!P:AO,26,0),10) -> 2024-01-29 | J13: =IF(I13=E13,"O","X") -> O | K13: =VLOOKUP(C13, '국내평가(ORS)'!P:AL, 23, 0) -> [보완2차]보완요청 2024-08-19 | L13: =VLOOKUP(C13, '국내평가(ORS)'!A:AL, 2, 0) -> 보완2차_보완중 | M13: 승인 전 | N13: 선택 | O13: 선택 | P13: =IF(AND(H13<>"반려", L13<>"반려"),"검토가능","") -> 검토가능 | Q13: 보완요청 | R13: 사업자 | S13: 45380 | T13: KECM_조수민 | U13: 제출서류 미비로 보완 요청. 보완 요청 통보 문구 기재(공단 통보)
A14: 12 | B14: 단일감축사업 | C14: 부산경남우유협동조합의 B-C유에서 도시가스(LNG)로 연료전환을 통한 온실가스 배출 외부사업 | D14: 부산경남우유협동조합 | E14: =VLOOKUP(C14,'외부사업 비공개승인관리_국내'!$C:$H,4,FALSE) -> 2024-07-02 | F14: =VLOOKUP(C14,'외부사업 비공개승인관리_국내'!$C:$H,5,FALSE) -> 산업통상부 | G14: =VLOOKUP(C14,'외부사업 비공개승인관리_국내'!$C:$H,6,FALSE) -> 2024-09-19 | H14: =VLOOKUP(C14,'외부사업 비공개승인관리_국내'!$C:$H,3,FALSE) -> 심의완료 | I14: =LEFT(VLOOKUP(C14,'국내평가(ORS)'!P:AO,26,0),10) -> 2023-11-16 | J14: =IF(I14=E14,"O","X") -> X | K14: =VLOOKUP(C14, '국내평가(ORS)'!P:AL, 23, 0) -> [보완3차]심의승인 2024-09-19 | L14: =VLOOKUP(C14, '국내평가(ORS)'!A:AL, 2, 0) -> 승인 | N14: 심의승인 | O14: 종결 | Q14: 심의승인 | R14: 종결 | S14: 45567 | T14: 에코시안_김명은 | AC14: 업체정보보호(내부 정보)
A15: 13 | B15: 단일감축사업 | C15: 씨큐브의 LPG에서 도시가스(LNG)로 연료전환을 통한 온실가스 배출 외부사업 | D15: 씨큐브(주) | E15: =VLOOKUP(C15,'외부사업 비공개승인관리_국내'!$C:$H,4,FALSE) -> 2024-10-11 | F15: =VLOOKUP(C15,'외부사업 비공개승인관리_국내'!$C:$H,5,FALSE) -> 산업통상부 | G15: =VLOOKUP(C15,'외부사업 비공개승인관리_국내'!$C:$H,6,FALSE) -> 2024-12-10 | H15: =VLOOKUP(C15,'외부사업 비공개승인관리_국내'!$C:$H,3,FALSE) -> 심의완료 | I15: =LEFT(VLOOKUP(C15,'국내평가(ORS)'!P:AO,26,0),10) -> 2023-08-18 | J15: =IF(I15=E15,"O","X") -> X | K15: =VLOOKUP(C15, '국내평가(ORS)'!P:AL, 23, 0) -> [보완3차]심의승인 2024-12-10 | L15: =VLOOKUP(C15, '국내평가(ORS)'!A:AL, 2, 0) -> 승인 | M15: 승인 전 | N15: 선택 | O15: 선택 | Q15: 심의승인 | R15: 종결 | S15: 45638 | T15: KECM_이태준 | U15: 사업계획서 내용 중 비공개 필요 부분 정확히 명시 필요(사업계획서 증빙자료는 정보공개 대상 아님) | AC15: 업체정보보호(내부 정보)
A16: 14 | B16: 단일감축사업 | C16: 엠함안(주) 목질계 바이오매스 연료 이용 열 공급을 통한 수용가의 화석연료 절감 및 온실가스 감축사업 | D16: 엠함안 | E16: =VLOOKUP(C16,'외부사업 비공개승인관리_국내'!$C:$H,4,FALSE) -> 2025-02-27 | F16: =VLOOKUP(C16,'외부사업 비공개승인관리_국내'!$C:$H,5,FALSE) -> 산업통상부 | G16: =VLOOKUP(C16,'외부사업 비공개승인관리_국내'!$C:$H,6,FALSE) -> 2025-03-07 | H16: =VLOOKUP(C16,'외부사업 비공개승인관리_국내'!$C:$H,3,FALSE) -> 반려 | I16: =LEFT(VLOOKUP(C16,'국내평가(ORS)'!P:AO,26,0),10) -> 2021-12-22 | J16: =IF(I16=E16,"O","X") -> X | K16: =VLOOKUP(C16, '국내평가(ORS)'!P:AL, 23, 0) -> [보완3차]착수신고 2024-04-16 | L16: =VLOOKUP(C16, '국내평가(ORS)'!A:AL, 2, 0) -> 승인 | M16: 검토필요 | N16: 보완요청 | O16: 사업자 | P16: =IF(AND(H16<>"반려", L16<>"반려"),"검토가능","") | Q16: 반려완료 | R16: 종결 | S16: 45769 | T16: 에코시안_조영우 | U16: 사업자 반려 요청 | AC16: 업체정보보호(업무상 비밀)
A17: 15 | B17: 단일감축사업 | C17: 대림아스콘의 B-C유에서 도시가스(LNG)로 연료전환을 통한 온실가스 배출 감축사업 | D17: 대림아스콘(주) | E17: =VLOOKUP(C17,'외부사업 비공개승인관리_국내'!$C:$H,4,FALSE) -> 2022-06-07 | F17: =VLOOKUP(C17,'외부사업 비공개승인관리_국내'!$C:$H,5,FALSE) -> 산업통상부 | G17: =VLOOKUP(C17,'외부사업 비공개승인관리_국내'!$C:$H,6,FALSE) -> 2023-04-25 | H17: =VLOOKUP(C17,'외부사업 비공개승인관리_국내'!$C:$H,3,FALSE) -> 보완요청 | I17: =LEFT(VLOOKUP(C17,'국내평가(ORS)'!P:AO,26,0),10) -> 2022-06-07 | J17: =IF(I17=E17,"O","X") -> O | K17: =VLOOKUP(C17, '국내평가(ORS)'!P:AL, 23, 0) -> [보완2차]심의승인 2023-03-17 | L17: =VLOOKUP(C17, '국내평가(ORS)'!A:AL, 2, 0) -> 승인 | M17: 검토필요 | N17: 보완요청 | O17: 사업자 | P17: =IF(AND(H17<>"반려", L17<>"반려"),"검토가능","") -> 검토가능 | Q17: 보완요청 | R17: 사업자 | S17: 45012 | T17: 에코시안_조영우 | U17: 사업계획서 내용 중 비공개 필요 부분 정확히 명시 필요(사업계획서 증빙자료는 정보공개 대상 아님)) | AC17: 내부방침
A18: 16 | B18: 묶음감축사업 | C18: 부산 해운대 클린에너지 학교 태양광발전 묶음 감축사업 | D18: 부산광역시교육청 | E18: =VLOOKUP(C18,'외부사업 비공개승인관리_국내'!$C:$H,4,FALSE) -> 2022-06-02 | F18: =VLOOKUP(C18,'외부사업 비공개승인관리_국내'!$C:$H,5,FALSE) -> 기후에너지환경부 | G18: =VLOOKUP(C18,'외부사업 비공개승인관리_국내'!$C:$H,6,FALSE) -> 2022-08-16 | H18: =VLOOKUP(C18,'외부사업 비공개승인관리_국내'!$C:$H,3,FALSE) -> 반려 | I18: =LEFT(VLOOKUP(C18,'국내평가(ORS)'!P:AO,26,0),10) -> 2021-06-21 | J18: =IF(I18=E18,"O","X") -> X | K18: =VLOOKUP(C18, '국내평가(ORS)'!P:AL, 23, 0) -> [보완2차]착수신고 2022-01-06 | L18: =VLOOKUP(C18, '국내평가(ORS)'!A:AL, 2, 0) -> 승인 | M18: 검토필요 | N18: 반려 | O18: 종결 | P18: =IF(AND(H18<>"반려", L18<>"반려"),"검토가능","") | Q18: 반려완료 | R18: 종결 | S18: 10월 13일 | T18: 에코시안_정인혜 | U18: 사업자 반려 요청 | AC18: 개인정보보호
A19: 17 | B19: 단일감축사업 | C19: 동신산업 평택공장의 B-C유에서 LNG로 연료전환을 통한 온실가스 배출 감축사업 | D19: 동신산업(주) | E19: =VLOOKUP(C19,'외부사업 비공개승인관리_국내'!$C:$H,4,FALSE) -> 2021-06-10 | F19: =VLOOKUP(C19,'외부사업 비공개승인관리_국내'!$C:$H,5,FALSE) -> 산업통상부 | G19: =VLOOKUP(C19,'외부사업 비공개승인관리_국내'!$C:$H,6,FALSE) -> 2022-06-02 | H19: =VLOOKUP(C19,'외부사업 비공개승인관리_국내'!$C:$H,3,FALSE) -> 보완요청 | I19: =LEFT(VLOOKUP(C19,'국내평가(ORS)'!P:AO,26,0),10) -> 2017-08-08 | J19: =IF(I19=E19,"O","X") -> X | K19: =VLOOKUP(C19, '국내평가(ORS)'!P:AL, 23, 0) -> [보완1차]착수신고 2021-05-26 | L19: =VLOOKUP(C19, '국내평가(ORS)'!A:AL, 2, 0) -> 승인 | M19: 검토필요 | N19: 보완요청 | O19: 사업자 | P19: =IF(AND(H19<>"반려", L19<>"반려"),"검토가능","") -> 검토가능 | Q19: 보완요청 | R19: 사업자 | S19: 5월 26일 | T19: 에코시안_정인혜 | U19: 사업계획서 내 보안유지 필요부분 구체화 필요 | AC19: 내부방침
A20: 18 | B20: 프로그램감축사업 | C20: 서울시사회복지협의회 태양광발전설비 설치를 통한 프로그램 온실가스 배출 감축사업 | D20: 사회복지법인 서울특별시사회복지 | E20: =VLOOKUP(C20,'외부사업 비공개승인관리_국내'!$C:$H,4,FALSE) -> 2021-05-03 | F20: =VLOOKUP(C20,'외부사업 비공개승인관리_국내'!$C:$H,5,FALSE) -> 기후에너지환경부 | G20: =VLOOKUP(C20,'외부사업 비공개승인관리_국내'!$C:$H,6,FALSE) -> 2025-02-25 | H20: =VLOOKUP(C20,'외부사업 비공개승인관리_국내'!$C:$H,3,FALSE) -> 반려 | I20: =LEFT(VLOOKUP(C20,'국내평가(ORS)'!P:AO,26,0),10) -> 2021-05-03 | J20: =IF(I20=E20,"O","X") -> O | K20: =VLOOKUP(C20, '국내평가(ORS)'!P:AL, 23, 0) -> 평가반려 2023-03-20 | L20: =VLOOKUP(C20, '국내평가(ORS)'!A:AL, 2, 0) -> 반려 | M20: X | N20: 선택 | O20: 선택 | P20: =IF(AND(H20<>"반려", L20<>"반려"),"검토가능","") | Q20: 선택 | R20: 종결 | S20: 5월 26일
A21: 19 | B21: 프로그램감축사업 | C21: 서울시사회복지협의회 태양광발전설비 설치를 통한 프로그램 온실가스 배출 감축사업 | D21: 사회복지법인 서울특별시사회복지 | E21: =VLOOKUP(C21,'외부사업 비공개승인관리_국내'!$C:$H,4,FALSE) -> 2021-05-03 | F21: =VLOOKUP(C21,'외부사업 비공개승인관리_국내'!$C:$H,5,FALSE) -> 기후에너지환경부 | G21: =VLOOKUP(C21,'외부사업 비공개승인관리_국내'!$C:$H,6,FALSE) -> 2025-02-25 | H21: =VLOOKUP(C21,'외부사업 비공개승인관리_국내'!$C:$H,3,FALSE) -> 반려 | I21: =LEFT(VLOOKUP(C21,'국내평가(ORS)'!P:AO,26,0),10) -> 2021-05-03 | J21: =IF(I21=E21,"O","X") -> O | K21: =VLOOKUP(C21, '국내평가(ORS)'!P:AL, 23, 0) -> 평가반려 2023-03-20 | L21: =VLOOKUP(C21, '국내평가(ORS)'!A:AL, 2, 0) -> 반려 | M21: X | N21: 선택 | O21: 선택 | P21: =IF(AND(H21<>"반려", L21<>"반려"),"검토가능","") | Q21: 선택 | R21: 종결 | S21: 5월 26일
A22: 20 | B22: 묶음감축사업 | C22: 공동폐수처리장의 고효율 터보블로워 도입을 통한 온실가스 감축사업 | D22: 부산녹산표면처리조합 | E22: =VLOOKUP(C22,'외부사업 비공개승인관리_국내'!$C:$H,4,FALSE) -> 2021-04-15 | F22: =VLOOKUP(C22,'외부사업 비공개승인관리_국내'!$C:$H,5,FALSE) -> 산업통상부 | G22: =VLOOKUP(C22,'외부사업 비공개승인관리_국내'!$C:$H,6,FALSE) -> 2025-02-25 | H22: =VLOOKUP(C22,'외부사업 비공개승인관리_국내'!$C:$H,3,FALSE) -> 반려 | I22: =LEFT(VLOOKUP(C22,'국내평가(ORS)'!P:AO,26,0),10) -> 2021-04-15 | J22: =IF(I22=E22,"O","X") -> O | K22: =VLOOKUP(C22, '국내평가(ORS)'!P:AL, 23, 0) -> 평가반려 2021-08-12 | L22: =VLOOKUP(C22, '국내평가(ORS)'!A:AL, 2, 0) -> 반려 | M22: X | N22: 선택 | O22: 선택 | P22: =IF(AND(H22<>"반려", L22<>"반려"),"검토가능","") | Q22: 선택 | R22: 종결 | S22: 5월 26일
A23: 21 | B23: 단일감축사업 | C23: 한미약품의 경유에서 LNG로 연료전환을 통한 온실가스 배출 감축사업 | D23: 한미약품(주) | E23: =VLOOKUP(C23,'외부사업 비공개승인관리_국내'!$C:$H,4,FALSE) -> 2021-02-04 | F23: =VLOOKUP(C23,'외부사업 비공개승인관리_국내'!$C:$H,5,FALSE) -> 산업통상부 | G23: =VLOOKUP(C23,'외부사업 비공개승인관리_국내'!$C:$H,6,FALSE) -> 2022-06-02 | H23: =VLOOKUP(C23,'외부사업 비공개승인관리_국내'!$C:$H,3,FALSE) -> 보완요청 | I23: =LEFT(VLOOKUP(C23,'국내평가(ORS)'!P:AO,26,0),10) -> 2017-08-11 | J23: =IF(I23=E23,"O","X") -> X | K23: =VLOOKUP(C23, '국내평가(ORS)'!P:AL, 23, 0) -> [보완2차]착수신고 2021-02-09 | L23: =VLOOKUP(C23, '국내평가(ORS)'!A:AL, 2, 0) -> 승인 | M23: 검토필요 | N23: 보완요청 | O23: 사업자 | P23: =IF(AND(H23<>"반려", L23<>"반려"),"검토가능","") -> 검토가능 | Q23: 보완요청 | R23: 사업자 | S23: 5월 26일 | T23: 에코시안_정인혜 | U23: 사업계획서 내 보안유지 필요부분 구체화 필요 | AC23: 내부방침
A24: 22 | B24: 단일감축사업 | C24: 검상산업단지 스팀생산 노후 LNG보일러 교체사업 | D24: 주식회사에코시안 | E24: =VLOOKUP(C24,'외부사업 비공개승인관리_국내'!$C:$H,4,FALSE) -> 2020-12-21 | F24: =VLOOKUP(C24,'외부사업 비공개승인관리_국내'!$C:$H,5,FALSE) -> 산업통상부 | G24: =VLOOKUP(C24,'외부사업 비공개승인관리_국내'!$C:$H,6,FALSE) -> 2025-02-25 | H24: =VLOOKUP(C24,'외부사업 비공개승인관리_국내'!$C:$H,3,FALSE) -> 반려 | I24: =LEFT(VLOOKUP(C24,'국내평가(ORS)'!P:AO,26,0),10) -> 2020-12-21 | J24: =IF(I24=E24,"O","X") -> O | K24: =VLOOKUP(C24, '국내평가(ORS)'!P:AL, 23, 0) -> [보완1차]평가반려 2021-05-28 | L24: =VLOOKUP(C24, '국내평가(ORS)'!A:AL, 2, 0) -> 반려 | M24: X | N24: 선택 | O24: 선택 | P24: =IF(AND(H24<>"반려", L24<>"반려"),"검토가능","") | Q24: 선택 | R24: 종결 | S24: 5월 26일
A25: 23 | B25: 단일감축사업 | C25: 태형기업(주) 양주사업장의 B-C유에서 도시가스(LNG)로 연료전환을 통한 온실가스(CO2) 배출 감축사업 | D25: 태형기업(주) | E25: =VLOOKUP(C25,'외부사업 비공개승인관리_국내'!$C:$H,4,FALSE) -> 2020-10-27 | F25: =VLOOKUP(C25,'외부사업 비공개승인관리_국내'!$C:$H,5,FALSE) -> 산업통상부 | G25: =VLOOKUP(C25,'외부사업 비공개승인관리_국내'!$C:$H,6,FALSE) -> 2022-06-02 | H25: =VLOOKUP(C25,'외부사업 비공개승인관리_국내'!$C:$H,3,FALSE) -> 보완요청 | I25: =LEFT(VLOOKUP(C25,'국내평가(ORS)'!P:AO,26,0),10) -> 2017-12-27 | J25: =IF(I25=E25,"O","X") -> X | K25: =VLOOKUP(C25, '국내평가(ORS)'!P:AL, 23, 0) -> [보완2차]착수신고 2021-08-25 | L25: =VLOOKUP(C25, '국내평가(ORS)'!A:AL, 2, 0) -> 승인 | M25: 검토필요 | N25: 보완요청 | O25: 사업자 | P25: =IF(AND(H25<>"반려", L25<>"반려"),"검토가능","") -> 검토가능 | Q25: 보완요청 | R25: 사업자 | S25: 5월 26일 | T25: 에코시안_정인혜 | U25: 사업계획서 내 보안유지 필요부분 구체화 필요 | AC25: 내부방침
A26: 24 | B26: 단일감축사업 | C26: (주)선일로에스의 B-A유에서 LNG로 연료전환을 통한 온실가스 배출 감축사업 | D26: (주)선일로에스 | E26: =VLOOKUP(C26,'외부사업 비공개승인관리_국내'!$C:$H,4,FALSE) -> 2020-10-05 | F26: =VLOOKUP(C26,'외부사업 비공개승인관리_국내'!$C:$H,5,FALSE) -> 산업통상부 | G26: =VLOOKUP(C26,'외부사업 비공개승인관리_국내'!$C:$H,6,FALSE) -> 2022-06-02 | H26: =VLOOKUP(C26,'외부사업 비공개승인관리_국내'!$C:$H,3,FALSE) -> 보완요청 | I26: =LEFT(VLOOKUP(C26,'국내평가(ORS)'!P:AO,26,0),10) -> 2017-12-07 | J26: =IF(I26=E26,"O","X") -> X | K26: =VLOOKUP(C26, '국내평가(ORS)'!P:AL, 23, 0) -> [보완3차]착수신고 2022-01-04 | L26: =VLOOKUP(C26, '국내평가(ORS)'!A:AL, 2, 0) -> 승인 | M26: 검토필요 | N26: 보완요청 | O26: 사업자 | P26: =IF(AND(H26<>"반려", L26<>"반려"),"검토가능","") -> 검토가능 | Q26: 보완요청 | R26: 사업자 | S26: 5월 26일 | T26: 에코시안_정인혜 | U26: 사업계획서 내 보안유지 필요부분 구체화 필요 | AC26: 내부방침
A27: 25 | B27: 단일감축사업 | C27: (주)덕산의 신재 및 재생 드라이어의 B-C유에서 도시가스(LNG)로 연료전환을 통한 온실가스 배출 감축사업 | D27: (주) 덕 산 | E27: =VLOOKUP(C27,'외부사업 비공개승인관리_국내'!$C:$H,4,FALSE) -> 2020-09-29 | F27: =VLOOKUP(C27,'외부사업 비공개승인관리_국내'!$C:$H,5,FALSE) -> 산업통상부 | G27: =VLOOKUP(C27,'외부사업 비공개승인관리_국내'!$C:$H,6,FALSE) -> 2022-06-02 | H27: =VLOOKUP(C27,'외부사업 비공개승인관리_국내'!$C:$H,3,FALSE) -> 보완요청 | I27: =LEFT(VLOOKUP(C27,'국내평가(ORS)'!P:AO,26,0),10) -> 2020-09-29 | J27: =IF(I27=E27,"O","X") -> O | K27: =VLOOKUP(C27, '국내평가(ORS)'!P:AL, 23, 0) -> [보완1차]착수신고 2022-05-30 | L27: =VLOOKUP(C27, '국내평가(ORS)'!A:AL, 2, 0) -> 승인 | M27: 검토필요 | N27: 보완요청 | O27: 사업자 | P27: =IF(AND(H27<>"반려", L27<>"반려"),"검토가능","") -> 검토가능 | Q27: 선택 | R27: 선택 | S27: 5월 26일 | T27: 에코시안_박세은 | U27: 사업계획서 내 보안유지 필요부분 구체화 필요 | AC27: 내부방침 | AD27: 이력이 반려이므로 사업반려에 포함됨
A28: 26 | B28: 단일감축사업 | C28: 에스오엠의 정제유에서 도시가스(LNG)로 연료전환을 통한 온실가스 배출 감축사업 | D28: 에스오엠 | E28: =VLOOKUP(C28,'외부사업 비공개승인관리_국내'!$C:$H,4,FALSE) -> 2020-09-21 | F28: =VLOOKUP(C28,'외부사업 비공개승인관리_국내'!$C:$H,5,FALSE) -> 산업통상부 | G28: =VLOOKUP(C28,'외부사업 비공개승인관리_국내'!$C:$H,6,FALSE) -> 2022-06-02 | H28: =VLOOKUP(C28,'외부사업 비공개승인관리_국내'!$C:$H,3,FALSE) -> 보완요청 | I28: =LEFT(VLOOKUP(C28,'국내평가(ORS)'!P:AO,26,0),10) -> 2020-09-21 | J28: =IF(I28=E28,"O","X") -> O | K28: =VLOOKUP(C28, '국내평가(ORS)'!P:AL, 23, 0) -> [보완3차]착수신고 2022-10-20 | L28: =VLOOKUP(C28, '국내평가(ORS)'!A:AL, 2, 0) -> 승인 | M28: 검토필요 | N28: 보완요청 | O28: 사업자 | P28: =IF(AND(H28<>"반려", L28<>"반려"),"검토가능","") -> 검토가능 | Q28: 보완요청 | R28: 사업자 | S28: 5월 26일 | T28: 에코시안_박세은 | U28: 사업계획서 내 보안유지 필요부분 구체화 필요 | AC28: 내부방침
A29: 27 | B29: 단일감축사업 | C29: 구미시 LED 가로등 교체를 통한 전력사용량 절감 및 온실가스 감축사업 | D29: 자이에스앤디(주) | E29: =VLOOKUP(C29,'외부사업 비공개승인관리_국내'!$C:$H,4,FALSE) -> 2020-09-09 | F29: =VLOOKUP(C29,'외부사업 비공개승인관리_국내'!$C:$H,5,FALSE) -> 산업통상부 | G29: =VLOOKUP(C29,'외부사업 비공개승인관리_국내'!$C:$H,6,FALSE) -> 2025-02-25 | H29: =VLOOKUP(C29,'외부사업 비공개승인관리_국내'!$C:$H,3,FALSE) -> 반려 | I29: =LEFT(VLOOKUP(C29,'국내평가(ORS)'!P:AO,26,0),10) -> 2020-09-09 | J29: =IF(I29=E29,"O","X") -> O | K29: =VLOOKUP(C29, '국내평가(ORS)'!P:AL, 23, 0) -> 평가반려 2021-07-14 | L29: =VLOOKUP(C29, '국내평가(ORS)'!A:AL, 2, 0) -> 반려 | M29: X | N29: 선택 | O29: 선택 | P29: =IF(AND(H29<>"반려", L29<>"반려"),"검토가능","") | Q29: 선택 | R29: 종결 | S29: 5월 26일
A30: 28 | B30: 단일감축사업 | C30: 부천수지의 B-C유에서 도시가스(LNG)로 연료전환을 통한 온실가스 배출 감축사업 | D30: (주)부천수지 | E30: =VLOOKUP(C30,'외부사업 비공개승인관리_국내'!$C:$H,4,FALSE) -> 2020-07-06 | F30: =VLOOKUP(C30,'외부사업 비공개승인관리_국내'!$C:$H,5,FALSE) -> 산업통상부 | G30: =VLOOKUP(C30,'외부사업 비공개승인관리_국내'!$C:$H,6,FALSE) -> 2022-06-02 | H30: =VLOOKUP(C30,'외부사업 비공개승인관리_국내'!$C:$H,3,FALSE) -> 보완요청 | I30: =LEFT(VLOOKUP(C30,'국내평가(ORS)'!P:AO,26,0),10) -> 2020-07-06 | J30: =IF(I30=E30,"O","X") -> O | K30: =VLOOKUP(C30, '국내평가(ORS)'!P:AL, 23, 0) -> [보완1차]착수신고 2022-06-10 | L30: =VLOOKUP(C30, '국내평가(ORS)'!A:AL, 2, 0) -> 승인 | M30: 검토필요 | N30: 보완요청 | O30: 사업자 | P30: =IF(AND(H30<>"반려", L30<>"반려"),"검토가능","") -> 검토가능 | Q30: 보완요청 | R30: 사업자 | S30: 5월 26일 | T30: 에코시안_박세은 | U30: 사업계획서 내 보안유지 필요부분 구체화 필요 | AC30: 내부방침
A31: 29 | B31: 단일감축사업 | C31: 서울금속공업의 정제유에서 LNG로 연료전환을 통한 온실가스 배출 감축사업 | D31: 서울금속공업(주) | E31: =VLOOKUP(C31,'외부사업 비공개승인관리_국내'!$C:$H,4,FALSE) -> 2020-06-24 | F31: =VLOOKUP(C31,'외부사업 비공개승인관리_국내'!$C:$H,5,FALSE) -> 산업통상부 | G31: =VLOOKUP(C31,'외부사업 비공개승인관리_국내'!$C:$H,6,FALSE) -> 2026-02-06 | H31: =VLOOKUP(C31,'외부사업 비공개승인관리_국내'!$C:$H,3,FALSE) -> 보완요청 | I31: =LEFT(VLOOKUP(C31,'국내평가(ORS)'!P:AO,26,0),10) -> 2017-12-29 | J31: =IF(I31=E31,"O","X") -> X | K31: =VLOOKUP(C31, '국내평가(ORS)'!P:AL, 23, 0) -> 평가반려 2021-05-17 | L31: =VLOOKUP(C31, '국내평가(ORS)'!A:AL, 2, 0) -> 반려 | M31: X | N31: 선택 | O31: 선택 | P31: =IF(AND(H31<>"반려", L31<>"반려"),"검토가능","") | Q31: 보완요청 | R31: 사업자 | S31: 5월 26일 | T31: 미정 | U31: 기 승인 사업, 사업변경신청 후 변경신청이 반려되었으나, 승인된 사업의 정보비공개 평가 필요 | AC31: 내부방침 | AD31: 사업 반려가 아니라 변경신청 반려임
A32: 30 | B32: 단일감축사업 | C32: 우성세라믹스공업의 LPG에서 LNG로 연료전환을 통한 온실가스 배출 감축사업 | D32: 우성세라믹스공업(주) | E32: =VLOOKUP(C32,'외부사업 비공개승인관리_국내'!$C:$H,4,FALSE) -> 2020-06-24 | F32: =VLOOKUP(C32,'외부사업 비공개승인관리_국내'!$C:$H,5,FALSE) -> 산업통상부 | G32: =VLOOKUP(C32,'외부사업 비공개승인관리_국내'!$C:$H,6,FALSE) -> 2022-06-02 | H32: =VLOOKUP(C32,'외부사업 비공개승인관리_국내'!$C:$H,3,FALSE) -> 보완요청 | I32: =LEFT(VLOOKUP(C32,'국내평가(ORS)'!P:AO,26,0),10) -> 2017-12-07 | J32: =IF(I32=E32,"O","X") -> X | K32: =VLOOKUP(C32, '국내평가(ORS)'!P:AL, 23, 0) -> [보완2차]착수신고 2021-04-02 | L32: =VLOOKUP(C32, '국내평가(ORS)'!A:AL, 2, 0) -> 승인 | M32: 검토필요 | N32: 보완요청 | O32: 사업자 | P32: =IF(AND(H32<>"반려", L32<>"반려"),"검토가능","") -> 검토가능 | Q32: 보완요청 | R32: 사업자 | S32: 5월 26일 | T32: 에코시안_박세은 | U32: 사업계획서 내 보안유지 필요부분 구체화 필요 | AC32: 내부방침
A33: 31 | B33: 단일감축사업 | C33: 덕성 인천사업장의 B-A유 및 B-C유에서 LNG로 연료전환을 통한 온실가스 배출 감축사업 | D33: (주)덕성 | E33: =VLOOKUP(C33,'외부사업 비공개승인관리_국내'!$C:$H,4,FALSE) -> 2020-04-27 | F33: =VLOOKUP(C33,'외부사업 비공개승인관리_국내'!$C:$H,5,FALSE) -> 산업통상부 | G33: =VLOOKUP(C33,'외부사업 비공개승인관리_국내'!$C:$H,6,FALSE) -> 2022-06-02 | H33: =VLOOKUP(C33,'외부사업 비공개승인관리_국내'!$C:$H,3,FALSE) -> 보완요청 | I33: =LEFT(VLOOKUP(C33,'국내평가(ORS)'!P:AO,26,0),10) -> 2018-10-17 | J33: =IF(I33=E33,"O","X") -> X | K33: =VLOOKUP(C33, '국내평가(ORS)'!P:AL, 23, 0) -> [보완3차]착수신고 2021-03-22 | L33: =VLOOKUP(C33, '국내평가(ORS)'!A:AL, 2, 0) -> 승인 | M33: 검토필요 | N33: 보완요청 | O33: 사업자 | P33: =IF(AND(H33<>"반려", L33<>"반려"),"검토가능","") -> 검토가능 | Q33: 보완요청 | R33: 사업자 | S33: 5월 26일 | T33: 에코시안_박세은 | U33: 사업계획서 내 보안유지 필요부분 구체화 필요 | AC33: 내부방침
A34: 32 | B34: 단일감축사업 | C34: 덕성 수원사업장의 B-A유에서 LNG로 연료전환을 통한 온실가스 배출 감축사업 | D34: (주)덕성 | E34: =VLOOKUP(C34,'외부사업 비공개승인관리_국내'!$C:$H,4,FALSE) -> 2020-04-27 | F34: =VLOOKUP(C34,'외부사업 비공개승인관리_국내'!$C:$H,5,FALSE) -> 산업통상부 | G34: =VLOOKUP(C34,'외부사업 비공개승인관리_국내'!$C:$H,6,FALSE) -> 2022-06-02 | H34: =VLOOKUP(C34,'외부사업 비공개승인관리_국내'!$C:$H,3,FALSE) -> 보완요청 | I34: =LEFT(VLOOKUP(C34,'국내평가(ORS)'!P:AO,26,0),10) -> 2017-12-26 | J34: =IF(I34=E34,"O","X") -> X | K34: =VLOOKUP(C34, '국내평가(ORS)'!P:AL, 23, 0) -> [보완3차]착수신고 2020-04-27 | L34: =VLOOKUP(C34, '국내평가(ORS)'!A:AL, 2, 0) -> 승인 | M34: 검토필요 | N34: 보완요청 | O34: 사업자 | P34: =IF(AND(H34<>"반려", L34<>"반려"),"검토가능","") -> 검토가능 | Q34: 보완요청 | R34: 사업자 | S34: 5월 26일 | T34: 에코시안_박세은 | U34: 사업계획서 내 보안유지 필요부분 구체화 필요 | AC34: 내부방침
A35: 33 | B35: 단일감축사업 | C35: 부옥물산의 B-C유에서 LNG로 연료전환을 통한 온실가스 배출 감축사업 | D35: 부옥물산(주) | E35: =VLOOKUP(C35,'외부사업 비공개승인관리_국내'!$C:$H,4,FALSE) -> 2020-04-14 | F35: =VLOOKUP(C35,'외부사업 비공개승인관리_국내'!$C:$H,5,FALSE) -> 산업통상부 | G35: =VLOOKUP(C35,'외부사업 비공개승인관리_국내'!$C:$H,6,FALSE) -> 2022-06-02 | H35: =VLOOKUP(C35,'외부사업 비공개승인관리_국내'!$C:$H,3,FALSE) -> 보완요청 | I35: =LEFT(VLOOKUP(C35,'국내평가(ORS)'!P:AO,26,0),10) -> 2018-10-04 | J35: =IF(I35=E35,"O","X") -> X | K35: =VLOOKUP(C35, '국내평가(ORS)'!P:AL, 23, 0) -> [보완3차]착수신고 2020-04-14 | L35: =VLOOKUP(C35, '국내평가(ORS)'!A:AL, 2, 0) -> 승인 | M35: 검토필요 | N35: 보완요청 | O35: 사업자 | P35: =IF(AND(H35<>"반려", L35<>"반려"),"검토가능","") -> 검토가능 | Q35: 보완요청 | R35: 사업자 | S35: 5월 26일 | T35: 에코시안_박세은 | U35: 사업계획서 내 보안유지 필요부분 구체화 필요 | AC35: 내부방침
A36: 34 | B36: 단일감축사업 | C36: 삼승텍스타일의 LPG에서 LNG로 연료전환을 통한 온실가스 배출 감축사업 | D36: 삼승텍스타일[주] | E36: =VLOOKUP(C36,'외부사업 비공개승인관리_국내'!$C:$H,4,FALSE) -> 2020-03-06 | F36: =VLOOKUP(C36,'외부사업 비공개승인관리_국내'!$C:$H,5,FALSE) -> 산업통상부 | G36: =VLOOKUP(C36,'외부사업 비공개승인관리_국내'!$C:$H,6,FALSE) -> 2025-02-25 | H36: =VLOOKUP(C36,'외부사업 비공개승인관리_국내'!$C:$H,3,FALSE) -> 반려 | I36: =LEFT(VLOOKUP(C36,'국내평가(ORS)'!P:AO,26,0),10) -> 2020-03-06 | J36: =IF(I36=E36,"O","X") -> O | K36: =VLOOKUP(C36, '국내평가(ORS)'!P:AL, 23, 0) -> 평가반려 2021-05-10 | L36: =VLOOKUP(C36, '국내평가(ORS)'!A:AL, 2, 0) -> 반려 | M36: X | N36: 선택 | O36: 선택 | P36: =IF(AND(H36<>"반려", L36<>"반려"),"검토가능","") | Q36: 선택 | R36: 종결 | S36: 5월 26일
A37: 35 | B37: 단일감축사업 | C37: 휴켐스(주) 신설 6질산 공장에서 발생하는 아산화질소(N2O) 배출량 저감사업 | D37: 휴켐스 주식회사 | E37: =VLOOKUP(C37,'외부사업 비공개승인관리_국내'!$C:$H,4,FALSE) -> 2020-02-24 | F37: =VLOOKUP(C37,'외부사업 비공개승인관리_국내'!$C:$H,5,FALSE) -> 산업통상부 | G37: =VLOOKUP(C37,'외부사업 비공개승인관리_국내'!$C:$H,6,FALSE) -> 2025-02-25 | H37: =VLOOKUP(C37,'외부사업 비공개승인관리_국내'!$C:$H,3,FALSE) -> 반려 | I37: =LEFT(VLOOKUP(C37,'국내평가(ORS)'!P:AO,26,0),10) -> 2020-02-24 | J37: =IF(I37=E37,"O","X") -> O | K37: =VLOOKUP(C37, '국내평가(ORS)'!P:AL, 23, 0) -> 평가반려 2020-05-21 | L37: =VLOOKUP(C37, '국내평가(ORS)'!A:AL, 2, 0) -> 반려 | M37: X | N37: 선택 | O37: 선택 | P37: =IF(AND(H37<>"반려", L37<>"반려"),"검토가능","") | Q37: 선택 | R37: 종결 | S37: 5월 26일
A38: 36 | B38: 묶음감축사업 | C38: 2019년 인천광역시 보안등 LED 교체 묶음 감축사업 | D38: 인천광역시 | E38: =VLOOKUP(C38,'외부사업 비공개승인관리_국내'!$C:$H,4,FALSE) -> 2019-12-31 | F38: =VLOOKUP(C38,'외부사업 비공개승인관리_국내'!$C:$H,5,FALSE) -> 산업통상부 | G38: =VLOOKUP(C38,'외부사업 비공개승인관리_국내'!$C:$H,6,FALSE) -> 2025-01-09 | H38: =VLOOKUP(C38,'외부사업 비공개승인관리_국내'!$C:$H,3,FALSE) -> 보완요청 | I38: =LEFT(VLOOKUP(C38,'국내평가(ORS)'!P:AO,26,0),10) -> 2019-12-31 | J38: =IF(I38=E38,"O","X") -> O | K38: =VLOOKUP(C38, '국내평가(ORS)'!P:AL, 23, 0) -> [보완3차]문서재제출요청 2022-10-20 | L38: =VLOOKUP(C38, '국내평가(ORS)'!A:AL, 2, 0) -> 보완3차_문서보완중 | M38: 승인 전 | N38: 선택 | O38: 선택 | P38: =IF(AND(H38<>"반려", L38<>"반려"),"검토가능","") -> 검토가능 | Q38: 보완요청 | R38: 사업자 | S38: 45665 | T38: 미정 | U38: 제출서류 미비로 보완 요청. 보완 요청 통보 문구 기재(공단 통보)
A39: 37 | B39: 묶음감축사업 | C39: 2019년 인천광역시 도로조명 LED 교체 묶음 감축사업 | D39: 인천광역시 | E39: =VLOOKUP(C39,'외부사업 비공개승인관리_국내'!$C:$H,4,FALSE) -> 2019-12-31 | F39: =VLOOKUP(C39,'외부사업 비공개승인관리_국내'!$C:$H,5,FALSE) -> 산업통상부 | G39: =VLOOKUP(C39,'외부사업 비공개승인관리_국내'!$C:$H,6,FALSE) -> 2025-01-09 | H39: =VLOOKUP(C39,'외부사업 비공개승인관리_국내'!$C:$H,3,FALSE) -> 보완요청 | I39: =LEFT(VLOOKUP(C39,'국내평가(ORS)'!P:AO,26,0),10) -> 2019-12-31 | J39: =IF(I39=E39,"O","X") -> O | K39: =VLOOKUP(C39, '국내평가(ORS)'!P:AL, 23, 0) -> [보완3차]문서재제출요청 2022-10-18 | L39: =VLOOKUP(C39, '국내평가(ORS)'!A:AL, 2, 0) -> 보완3차_문서보완중 | M39: 승인 전 | N39: 선택 | O39: 선택 | P39: =IF(AND(H39<>"반려", L39<>"반려"),"검토가능","") -> 검토가능 | Q39: 보완요청 | R39: 사업자 | S39: 45665 | T39: 미정 | U39: 제출서류 미비로 보완 요청. 보완 요청 통보 문구 기재(공단 통보)
A40: 38 | B40: 프로그램감축사업 | C40: 인천광역시 주택 태양광 발전설비 보급 프로그램 감축사업 | D40: 인천광역시 | E40: =VLOOKUP(C40,'외부사업 비공개승인관리_국내'!$C:$H,4,FALSE) -> 2019-12-31 | F40: =VLOOKUP(C40,'외부사업 비공개승인관리_국내'!$C:$H,5,FALSE) -> 기후에너지환경부 | G40: =VLOOKUP(C40,'외부사업 비공개승인관리_국내'!$C:$H,6,FALSE) -> 2025-02-25 | H40: =VLOOKUP(C40,'외부사업 비공개승인관리_국내'!$C:$H,3,FALSE) -> 반려 | I40: =LEFT(VLOOKUP(C40,'국내평가(ORS)'!P:AO,26,0),10) -> 2021-12-27 | J40: =IF(I40=E40,"O","X") -> X | K40: =VLOOKUP(C40, '국내평가(ORS)'!P:AL, 23, 0) -> 문서재제출요청 2022-08-24 | L40: =VLOOKUP(C40, '국내평가(ORS)'!A:AL, 2, 0) -> 문서재제출 | M40: X | N40: 선택 | O40: 선택 | P40: =IF(AND(H40<>"반려", L40<>"반려"),"검토가능","") | Q40: 선택 | R40: 종결 | S40: 5월 26일
...

Sheet (비공개)국내인증
F1: 정보비공개 DB | L1: 국내인증 DB(참고용)
A2: 검증 | B2: 번호 | C2: 사업유형 | D2: 사업명 | E2: 업체명 | F2: 유효기간 | G2: 모니터링차수 | H2: 정보비공개 신청일 | I2: 관장기관 | J2: 처리일 | K2: 진행상태 | L2: 차수 | M2: 모니터링 기간 시작일 | N2: 사업 신청일 | O2: 평가 가능 여부 | P2: 검토대상 | Q2: 진행상태 | R2: 현 위치 | S2: 진행상태 | T2: 현 위치 | U2: 업데이트 | V2: 담당자 | W2: 비고 | X2: 권리 | Y2: 대외비 자료 | Z2: 계약서류 | AA2: 연료 사용량 | AB2: 공정 도식도 | AC2: 영업비밀 | AD2: 내규방침 제출여부 | AE2: 비공개 신청사유 | AF2: 특이사항
A3: =D3&L3&M3 -> 원주시 보안등 LED교체 ESCO용역사업1차2016-10-31 | B3: 1 | C3: 단일감축사업 | D3: 원주시 보안등 LED교체 ESCO용역사업 | E3: 원주시 | F3: =VLOOKUP(D3,'인증실적 비공개승인관리_국내'!$D:$K,3,FALSE) -> 2016-10-31~2023-10-30 | G3: =VLOOKUP(D3,'인증실적 비공개승인관리_국내'!$D:$K,4,FALSE) -> 1차 (2016-10-31~2016-10-31) | H3: =VLOOKUP(D3,'인증실적 비공개승인관리_국내'!$D:$K,6,FALSE) -> 2026-05-20 | I3: =VLOOKUP(D3,'인증실적 비공개승인관리_국내'!$D:$K,7,FALSE) -> 산업통상부 | J3: =VLOOKUP(D3,'인증실적 비공개승인관리_국내'!$D:$K,8,FALSE) -> 2026-05-22 | K3: =VLOOKUP(A3,'인증실적 비공개승인관리_국내'!$A:$N,8,FALSE) -> 보완요청 | L3: =LEFT(G3,FIND("차",G3)) -> 1차 | M3: =MID(G3,FINDB("(",G3),10) -> 2016-10-31 | N3: =LEFT(VLOOKUP(D3,'국내인증(ORS)'!O:BI,38,0),10) -> 2024-10-30 | O3: =IF(N3=#REF!,"O","X") -> #REF! | P3: 승인 전 | Q3: 선택 | R3: 선택 | S3: 보완요청 | T3: 사업자 | U3: 45992 | V3: 에코시안_남혜원 | W3: <신청사유> 본 외부사업의 사업계획서 상 비공개를 희망하는 부분 및 그 사유를 다음과 같이 기술함. 1.2. 사업의 위치 (1) 사업의 주소, 보안등 관리번호 - 이 사업의 대상인 도로조명의 주소, 등번호는 중요한 정보이며, 그 목록 전체를 원 주시가 일반에게 공개할 의무는 없으며, 오남용될 가능성도 있어 원주시는 이 정보의 공개를 원하지 않음 [근거: 공공기관의 정보공개에 관한 법률 제9조제1항제5호] 4. 모니터링 데이터 및 지표 - 본 외부사업의 베이스라인 및 모니터링 방법 등이 원주시 고유의 특성을 반영하여 구체적으로 기술되어 있기 때문에 정보공개를 원하지 않음. 또한, 이 보고서를 작성하기 위하여 원주시가 오랜 기간 동안 시간과 노력과 예산을 투자하여 작성한 영구성과물이기 때문에 무상으로 이를 일반인에게 공개하는 것은 공평하지 못하며, 시장질서에도 바람직하지 않다고 사료되므로 원주시는 비공개를 요청함 [근거: 공공기관의 정보공개에 관한 법률 제9조제1항제5호,제7호] <1차 통보> ∙ 「명세서 공개 심사위원회 구성 및 운영에 관한 규정」 [별표1]에 따라 비공개 신청사유를 하기와 같이 보완 요청 드립니다. - 모니터링보고서, 검증 보고서 내용 중 보안유지 필요 부분, 위치(page) 및 사유 구체화(증빙자료는 정보공개 대상 아님) - 필요 시 정보 비공개사유에 대한 증빙자료 제출 요청 ∙ 단, 투명성 원칙에 따라 민감사항이 모니터링보고서, 검증 보고서 내 문서에 포함되지 않아도 되는 경우(필수 작성 항목이 아닌 경우) 해당 사항은 증빙자료로만 제출하고 본 비공개 신청건은 철회 신청해주시기 바랍니다. | AE3: 업체정보보호(내부 정보)
A4: =D4&L4&M4 -> 2015년 춘천시 도로조명 LED 교체를 통한 묶음 감축사업1차2015-10-30 | B4: 2 | C4: 묶음감축사업 | D4: 2015년 춘천시 도로조명 LED 교체를 통한 묶음 감축사업 | E4: 춘천시 | F4: 2015-10-30~2025-10-29 | G4: 1차 (2015-10-30~2015-10-30) | H4: =VLOOKUP(D4,'인증실적 비공개승인관리_국내'!$D:$K,6,FALSE) -> 2024-08-26 | I4: =VLOOKUP(D4,'인증실적 비공개승인관리_국내'!$D:$K,7,FALSE) -> 산업통상부 | J4: =VLOOKUP(D4,'인증실적 비공개승인관리_국내'!$D:$K,8,FALSE) -> 2025-06-12 | K4: =VLOOKUP(A4,'인증실적 비공개승인관리_국내'!$A:$N,8,FALSE) -> 심의완료 | L4: =LEFT(G4,FIND("차",G4)) -> 1차 | M4: =MID(G4,FINDB("(",G4),10) -> 2015-10-30 | N4: =LEFT(VLOOKUP(D4,'국내인증(ORS)'!O:BI,38,0),10) -> 2023-01-11 | O4: =IF(N4=#REF!,"O","X") -> #REF! | P4: 승인 전 | Q4: 선택 | R4: 선택 | S4: 심의승인 | T4: 종결 | U4: 45833 | V4: 에코시안_조영우 | W4: 심의 승인
A5: =D5&L5&M5 -> 에이스침대 중부공장의 B-C유에서 도시가스(LNG)로 연료전환을 통한 온실가스 배출 감축사업1차2010-10-11 | B5: 3 | C5: 단일감축사업 | D5: 에이스침대 중부공장의 B-C유에서 도시가스(LNG)로 연료전환을 통한 온실가스 배출 감축사업 | E5: (주)에이스침대중부공장 | F5: 2010-10-11~2020-10-10 | G5: 1차 (2010-10-11~2010-10-11) | H5: =VLOOKUP(D5,'인증실적 비공개승인관리_국내'!$D:$K,6,FALSE) -> 2024-07-17 | I5: =VLOOKUP(D5,'인증실적 비공개승인관리_국내'!$D:$K,7,FALSE) -> 산업통상부 | J5: =VLOOKUP(D5,'인증실적 비공개승인관리_국내'!$D:$K,8,FALSE) -> 2024-09-19 | K5: =VLOOKUP(A5,'인증실적 비공개승인관리_국내'!$A:$N,8,FALSE) -> 심의완료 | L5: =LEFT(G5,FIND("차",G5)) -> 1차 | M5: =MID(G5,FINDB("(",G5),10) -> 2010-10-11 | N5: =LEFT(VLOOKUP(D5,'국내인증(ORS)'!O:BI,38,0),10) -> 2024-01-12 | O5: =IF(N5=#REF!,"O","X") -> #REF! | Q5: 심의승인 | R5: 종결 | S5: 심의승인 | T5: 종결 | U5: 45567 | V5: 에코시안_조은지 | AF5: 검토 기준 변경 전 승인 사업
A6: =D6&L6&M6 -> 카프로 N2O 저감 사업10차2021-01-01 | B6: 4 | C6: 단일감축사업 | D6: 카프로 N2O 저감 사업 | E6: 주식회사 카프로 | F6: 2011-06-09~2021-06-08 | G6: 10차 (2021-01-01~2021-01-01) | H6: =VLOOKUP(D6,'인증실적 비공개승인관리_국내'!$D:$K,6,FALSE) -> 2024-01-24 | I6: =VLOOKUP(D6,'인증실적 비공개승인관리_국내'!$D:$K,7,FALSE) -> 산업통상부 | J6: =VLOOKUP(D6,'인증실적 비공개승인관리_국내'!$D:$K,8,FALSE) -> 2024-06-17 | K6: =VLOOKUP(A6,'인증실적 비공개승인관리_국내'!$A:$N,8,FALSE) -> 보완요청 | L6: =LEFT(G6,FIND("차",G6)) -> 10차 | M6: =MID(G6,FINDB("(",G6),10) -> 2021-01-01 | N6: =LEFT(VLOOKUP(D6,'국내인증(ORS)'!O:BI,38,0),10) -> 2022-05-31 | O6: =IF(N6=#REF!,"O","X") -> #REF! | P6: 검토필요 | Q6: 보완요청 | R6: 사업자 | S6: 보완요청 | T6: 사업자 | U6: 45457 | V6: 에코시안_조영우 | W6: 모니터링보고서 및 검증보고서 내 비공개 필요 부분 정확히 명시 필요(모니터링보고서 증빙자료는 정보공개 대상 아님) | AE6: 업체정보보호(업무상 비밀)
A7: =D7&L7&M7 -> 덕성 인천사업장의 B-A유 및 B-C유에서 LNG로 연료전환을 통한 온실가스 배출 감축사업2차2020-11-01 | B7: 5 | C7: 단일감축사업 | D7: 덕성 인천사업장의 B-A유 및 B-C유에서 LNG로 연료전환을 통한 온실가스 배출 감축사업 | E7: (주)덕성 | F7: 2012-12-19~2022-12-18 | G7: 2차 (2020-11-01~2020-11-01) | H7: =VLOOKUP(D7,'인증실적 비공개승인관리_국내'!$D:$K,6,FALSE) -> 2023-11-24 | I7: =VLOOKUP(D7,'인증실적 비공개승인관리_국내'!$D:$K,7,FALSE) -> 산업통상부 | J7: =VLOOKUP(D7,'인증실적 비공개승인관리_국내'!$D:$K,8,FALSE) -> 2024-06-17 | K7: =VLOOKUP(A7,'인증실적 비공개승인관리_국내'!$A:$N,8,FALSE) -> 보완요청 | L7: =LEFT(G7,FIND("차",G7)) -> 2차 | M7: =MID(G7,FINDB("(",G7),10) -> 2020-11-01 | N7: =LEFT(VLOOKUP(D7,'국내인증(ORS)'!O:BI,38,0),10) -> 2023-09-25 | O7: =IF(N7=#REF!,"O","X") -> #REF! | P7: 검토필요 | Q7: 보완요청 | R7: 사업자 | S7: 보완요청 | T7: 사업자 | U7: 45457 | V7: 에코시안_조영우 | W7: 모니터링보고서 및 검증보고서 내 비공개 필요 부분 정확히 명시 필요(모니터링보고서 증빙자료는 정보공개 대상 아님) | AE7: 업체정보보호(업무상 비밀)
A8: =D8&L8&M8 -> 카프로 N2O 저감 사업11차2021-01-01 | B8: 6 | C8: 단일감축사업 | D8: 카프로 N2O 저감 사업 | E8: 주식회사 카프로 | F8: 2011-06-09~2021-06-08 | G8: 11차 (2021-01-01~2021-01-01) | H8: =VLOOKUP(D8,'인증실적 비공개승인관리_국내'!$D:$K,6,FALSE) -> 2024-01-24 | I8: =VLOOKUP(D8,'인증실적 비공개승인관리_국내'!$D:$K,7,FALSE) -> 산업통상부 | J8: =VLOOKUP(D8,'인증실적 비공개승인관리_국내'!$D:$K,8,FALSE) -> 2024-06-17 | K8: =VLOOKUP(A8,'인증실적 비공개승인관리_국내'!$A:$N,8,FALSE) -> 반려 | L8: =LEFT(G8,FIND("차",G8)) -> 11차 | M8: =MID(G8,FINDB("(",G8),10) -> 2021-01-01 | N8: =LEFT(VLOOKUP(D8,'국내인증(ORS)'!O:BI,38,0),10) -> 2022-05-31 | O8: =IF(N8=#REF!,"O","X") -> #REF! | P8: X | Q8: 선택 | R8: 선택 | S8: 선택 | T8: 종결 | U8: 45769 | W8: 반려 완료, 외부사업이 평가/인증 단계에서 반려
A9: =D9&L9&M9 -> 에이스침대 여주공장의 B-C유에서 도시가스(LNG)로 연료전환을 통한 온실가스 배출 감축사업1차2010-11-22 | B9: 7 | C9: 단일감축사업 | D9: 에이스침대 여주공장의 B-C유에서 도시가스(LNG)로 연료전환을 통한 온실가스 배출 감축사업 | E9: (주)에이스침대중부공장 | F9: 2010-11-22~2020-11-21 | G9: 1차 (2010-11-22~2010-11-22) | H9: =VLOOKUP(D9,'인증실적 비공개승인관리_국내'!$D:$K,6,FALSE) -> 2022-11-30 | I9: =VLOOKUP(D9,'인증실적 비공개승인관리_국내'!$D:$K,7,FALSE) -> 산업통상부 | J9: =VLOOKUP(D9,'인증실적 비공개승인관리_국내'!$D:$K,8,FALSE) -> 2023-06-19 | K9: =VLOOKUP(A9,'인증실적 비공개승인관리_국내'!$A:$N,8,FALSE) -> 보완요청 | L9: =LEFT(G9,FIND("차",G9)) -> 1차 | M9: =MID(G9,FINDB("(",G9),10) -> 2010-11-22 | N9: =LEFT(VLOOKUP(D9,'국내인증(ORS)'!O:BI,38,0),10) -> 2022-11-30 | O9: =IF(N9=#REF!,"O","X") -> #REF! | P9: 검토필요 | Q9: 보완요청 | R9: 사업자 | S9: 보완요청 | T9: 사업자 | U9: 45096 | V9: 에코시안_조영우 | W9: 모니터링보고서 및 검증보고서 내 보안유지 필요부분 구체화 필요 | AE9: 업체정보보호(업무상 비밀)
A10: =D10&L10&M10 -> 에스오엠의 정제유에서 도시가스(LNG)로 연료전환을 통한 온실가스 배출 감축사업1차2011-01-22 | B10: 8 | C10: 단일감축사업 | D10: 에스오엠의 정제유에서 도시가스(LNG)로 연료전환을 통한 온실가스 배출 감축사업 | E10: 에스오엠 | F10: 2011-01-22~2021-01-21 | G10: 1차 (2011-01-22~2011-01-22) | H10: =VLOOKUP(D10,'인증실적 비공개승인관리_국내'!$D:$K,6,FALSE) -> 2022-11-25 | I10: =VLOOKUP(D10,'인증실적 비공개승인관리_국내'!$D:$K,7,FALSE) -> 산업통상부 | J10: =VLOOKUP(D10,'인증실적 비공개승인관리_국내'!$D:$K,8,FALSE) -> 2024-06-17 | K10: =VLOOKUP(A10,'인증실적 비공개승인관리_국내'!$A:$N,8,FALSE) -> 보완요청 | L10: =LEFT(G10,FIND("차",G10)) -> 1차 | M10: =MID(G10,FINDB("(",G10),10) -> 2011-01-22 | N10: =LEFT(VLOOKUP(D10,'국내인증(ORS)'!O:BI,38,0),10) -> 2022-10-20 | O10: =IF(N10=#REF!,"O","X") -> #REF! | P10: 검토필요 | Q10: 보완요청 | R10: 사업자 | S10: 보완요청 | T10: 사업자 | U10: 45457 | V10: 에코시안_조영우 | W10: 모니터링보고서 및 검증보고서 내 비공개 필요 부분 정확히 명시 필요(모니터링보고서 증빙자료는 정보공개 대상 아님) | AE10: 내부방침
A11: =D11&L11&M11 -> 삼일이노팩의 B-C유에서 LNG로 연료전환을 통한 온실가스 배출 감축사업2차2020-07-01 | B11: 9 | C11: 단일감축사업 | D11: 삼일이노팩의 B-C유에서 LNG로 연료전환을 통한 온실가스 배출 감축사업 | E11: 주식회사 삼일이노팩 | F11: 2012-10-04~2022-10-03 | G11: 2차 (2020-07-01~2020-07-01) | H11: =VLOOKUP(D11,'인증실적 비공개승인관리_국내'!$D:$K,6,FALSE) -> 2022-11-15 | I11: =VLOOKUP(D11,'인증실적 비공개승인관리_국내'!$D:$K,7,FALSE) -> 산업통상부 | J11: =VLOOKUP(D11,'인증실적 비공개승인관리_국내'!$D:$K,8,FALSE) -> 2024-06-17 | K11: =VLOOKUP(A11,'인증실적 비공개승인관리_국내'!$A:$N,8,FALSE) -> 보완요청 | L11: =LEFT(G11,FIND("차",G11)) -> 2차 | M11: =MID(G11,FINDB("(",G11),10) -> 2020-07-01 | N11: =LEFT(VLOOKUP(D11,'국내인증(ORS)'!O:BI,38,0),10) -> 2022-11-15 | O11: =IF(N11=#REF!,"O","X") -> #REF! | P11: 검토필요 | Q11: 보완요청 | R11: 사업자 | S11: 보완요청 | T11: 사업자 | U11: 45457 | V11: 에코시안_조영우 | W11: 모니터링보고서 및 검증보고서 내 비공개 필요 부분 정확히 명시 필요(모니터링보고서 증빙자료는 정보공개 대상 아님) | AE11: 업체정보보호(업무상 비밀)
A12: =D12&L12&M12 -> 남부산업의 이온정제유에서 LNG로 연료전환을 통한 온실가스 배출 감축사업1차2015-03-01 | B12: 10 | C12: 단일감축사업 | D12: 남부산업의 이온정제유에서 LNG로 연료전환을 통한 온실가스 배출 감축사업 | E12: 남부산업[주] | F12: 2013-01-29~2023-01-28 | G12: 1차 (2015-03-01~2015-03-01) | H12: =VLOOKUP(D12,'인증실적 비공개승인관리_국내'!$D:$K,6,FALSE) -> 2022-07-20 | I12: =VLOOKUP(D12,'인증실적 비공개승인관리_국내'!$D:$K,7,FALSE) -> 산업통상부 | J12: =VLOOKUP(D12,'인증실적 비공개승인관리_국내'!$D:$K,8,FALSE) -> 2022-10-19 | K12: =VLOOKUP(A12,'인증실적 비공개승인관리_국내'!$A:$N,8,FALSE) -> 보완요청 | L12: =LEFT(G12,FIND("차",G12)) -> 1차 | M12: =MID(G12,FINDB("(",G12),10) -> 2015-03-01 | N12: =LEFT(VLOOKUP(D12,'국내인증(ORS)'!O:BI,38,0),10) -> 2021-09-29 | O12: =IF(N12=#REF!,"O","X") -> #REF! | P12: 검토필요 | Q12: 보완요청 | R12: 사업자 | S12: 보완요청 | T12: 사업자 | U12: 10월 13일 | V12: 에코시안 | W12: 모니터링보고서 및 검증보고서 내 보안유지 필요부분 구체화 필요 | AE12: 내부방침
A13: =D13&L13&M13 -> 동신산업 평택공장의 B-C유에서 LNG로 연료전환을 통한 온실가스 배출 감축사업1차2010-05-21 | B13: 11 | C13: 단일감축사업 | D13: 동신산업 평택공장의 B-C유에서 LNG로 연료전환을 통한 온실가스 배출 감축사업 | E13: 동신산업(주) | F13: 2008-07-30~2018-07-29 | G13: 1차 (2010-05-21~2010-05-21) | H13: =VLOOKUP(D13,'인증실적 비공개승인관리_국내'!$D:$K,6,FALSE) -> 2022-07-20 | I13: =VLOOKUP(D13,'인증실적 비공개승인관리_국내'!$D:$K,7,FALSE) -> 산업통상부 | J13: =VLOOKUP(D13,'인증실적 비공개승인관리_국내'!$D:$K,8,FALSE) -> 2022-10-19 | K13: =VLOOKUP(A13,'인증실적 비공개승인관리_국내'!$A:$N,8,FALSE) -> 보완요청 | L13: =LEFT(G13,FIND("차",G13)) -> 1차 | M13: =MID(G13,FINDB("(",G13),10) -> 2010-05-21 | N13: =LEFT(VLOOKUP(D13,'국내인증(ORS)'!O:BI,38,0),10) -> 2021-09-28 | O13: =IF(N13=#REF!,"O","X") -> #REF! | P13: 검토필요 | Q13: 보완요청 | R13: 사업자 | S13: 보완요청 | T13: 사업자 | U13: 10월 13일 | V13: 에코시안 | W13: 모니터링보고서 및 검증보고서 내 보안유지 필요부분 구체화 필요 | AE13: 내부방침
A14: =D14&L14&M14 -> 부천수지의 B-C유에서 도시가스(LNG)로 연료전환을 통한 온실가스 배출 감축사업1차2011-08-08 | B14: 12 | C14: 단일감축사업 | D14: 부천수지의 B-C유에서 도시가스(LNG)로 연료전환을 통한 온실가스 배출 감축사업 | E14: (주)부천수지 | F14: 2011-08-08~2021-08-07 | G14: 1차 (2011-08-08~2011-08-08) | H14: =VLOOKUP(D14,'인증실적 비공개승인관리_국내'!$D:$K,6,FALSE) -> 2022-06-10 | I14: =VLOOKUP(D14,'인증실적 비공개승인관리_국내'!$D:$K,7,FALSE) -> 산업통상부 | J14: =VLOOKUP(D14,'인증실적 비공개승인관리_국내'!$D:$K,8,FALSE) -> 2023-04-25 | K14: =VLOOKUP(A14,'인증실적 비공개승인관리_국내'!$A:$N,8,FALSE) -> 보완요청 | L14: =LEFT(G14,FIND("차",G14)) -> 1차 | M14: =MID(G14,FINDB("(",G14),10) -> 2011-08-08 | N14: =LEFT(VLOOKUP(D14,'국내인증(ORS)'!O:BI,38,0),10) -> 2022-06-10 | O14: =IF(N14=#REF!,"O","X") -> #REF! | P14: 검토필요 | Q14: 보완요청 | R14: 사업자 | S14: 보완요청 | T14: 사업자 | U14: 45012 | V14: 에코시안_조영우 | W14: 모니터링보고서 내용 중 비공개 필요 부분 정확히 명시 필요(모니터링보고서 증빙자료는 정보공개 대상 아님) | AE14: 내부방침
A15: =D15&L15&M15 -> 태림포장의 B-C유에서 LNG로 연료전환을 통한 온실가스 배출 감축사업1차2010-05-02 | B15: 13 | C15: 단일감축사업 | D15: 태림포장의 B-C유에서 LNG로 연료전환을 통한 온실가스 배출 감축사업 | E15: 태림포장(주) | F15: 2008-07-14~2018-07-13 | G15: 1차 (2010-05-02~2010-05-02) | H15: =VLOOKUP(D15,'인증실적 비공개승인관리_국내'!$D:$K,6,FALSE) -> 2022-06-10 | I15: =VLOOKUP(D15,'인증실적 비공개승인관리_국내'!$D:$K,7,FALSE) -> 산업통상부 | J15: =VLOOKUP(D15,'인증실적 비공개승인관리_국내'!$D:$K,8,FALSE) -> 2023-04-25 | K15: =VLOOKUP(A15,'인증실적 비공개승인관리_국내'!$A:$N,8,FALSE) -> 보완요청 | L15: =LEFT(G15,FIND("차",G15)) -> 1차 | M15: =MID(G15,FINDB("(",G15),10) -> 2010-05-02 | N15: =LEFT(VLOOKUP(D15,'국내인증(ORS)'!O:BI,38,0),10) -> 2022-06-10 | O15: =IF(N15=#REF!,"O","X") -> #REF! | P15: 검토필요 | Q15: 보완요청 | R15: 사업자 | S15: 보완요청 | T15: 사업자 | U15: 45012 | V15: 에코시안_조영우 | W15: 모니터링보고서 내용 중 비공개 필요 부분 정확히 명시 필요(모니터링보고서 증빙자료는 정보공개 대상 아님) | AE15: 내부방침
A16: =D16&L16&M16 -> (주)덕산의 신재 및 재생 드라이어의 B-C유에서 도시가스(LNG)로 연료전환을 통한 온실가스 배출 감축사업1차2020-01-22 | B16: 14 | C16: 단일감축사업 | D16: (주)덕산의 신재 및 재생 드라이어의 B-C유에서 도시가스(LNG)로 연료전환을 통한 온실가스 배출 감축사업 | E16: (주) 덕 산 | F16: 2020-01-22~2030-01-21 | G16: 1차 (2020-01-22~2020-01-22) | H16: =VLOOKUP(D16,'인증실적 비공개승인관리_국내'!$D:$K,6,FALSE) -> 2022-05-30 | I16: =VLOOKUP(D16,'인증실적 비공개승인관리_국내'!$D:$K,7,FALSE) -> 산업통상부 | J16: =VLOOKUP(D16,'인증실적 비공개승인관리_국내'!$D:$K,8,FALSE) -> 2023-04-25 | K16: =VLOOKUP(A16,'인증실적 비공개승인관리_국내'!$A:$N,8,FALSE) -> 보완요청 | L16: =LEFT(G16,FIND("차",G16)) -> 1차 | M16: =MID(G16,FINDB("(",G16),10) -> 2020-01-22 | N16: =LEFT(VLOOKUP(D16,'국내인증(ORS)'!O:BI,38,0),10) -> 2022-05-30 | O16: =IF(N16=#REF!,"O","X") -> #REF! | P16: 검토필요 | Q16: 보완요청 | R16: 사업자 | S16: 보완요청 | T16: 사업자 | U16: 45012 | V16: 에코시안_조영우 | W16: 모니터링보고서 내용 중 비공개 필요 부분 정확히 명시 필요(모니터링보고서 증빙자료는 정보공개 대상 아님) | AE16: 내부방침
A17: =D17&L17&M17 -> 대평산업개발의 정제유 및 B-C유에서 도시가스(LNG)로의 연료전환을 통한 온실가스 배출 감축사업1차2019-02-01 | B17: 15 | C17: 단일감축사업 | D17: 대평산업개발의 정제유 및 B-C유에서 도시가스(LNG)로의 연료전환을 통한 온실가스 배출 감축사업 | E17: (주)대평산업개발 | F17: 2019-02-01~2026-01-31 | G17: 1차 (2019-02-01~2019-02-01) | H17: =VLOOKUP(D17,'인증실적 비공개승인관리_국내'!$D:$K,6,FALSE) -> 2022-05-16 | I17: =VLOOKUP(D17,'인증실적 비공개승인관리_국내'!$D:$K,7,FALSE) -> 산업통상부 | J17: =VLOOKUP(D17,'인증실적 비공개승인관리_국내'!$D:$K,8,FALSE) -> 2023-04-25 | K17: =VLOOKUP(A17,'인증실적 비공개승인관리_국내'!$A:$N,8,FALSE) -> 보완요청 | L17: =LEFT(G17,FIND("차",G17)) -> 1차 | M17: =MID(G17,FINDB("(",G17),10) -> 2019-02-01 | N17: =LEFT(VLOOKUP(D17,'국내인증(ORS)'!O:BI,38,0),10) -> 2022-05-16 | O17: =IF(N17=#REF!,"O","X") -> #REF! | P17: 검토필요 | Q17: 보완요청 | R17: 사업자 | S17: 보완요청 | T17: 사업자 | U17: 45012 | V17: 에코시안_조영우 | W17: 모니터링보고서 내용 중 비공개 필요 부분 정확히 명시 필요(모니터링보고서 증빙자료는 정보공개 대상 아님) | AE17: 내부방침
A18: =D18&L18&M18 -> 덕산지에스의 부생연료유 2호에서 도시가스(LNG)로의 연료전환을 통한 온실가스 배출 감축사업1차2018-12-17 | B18: 16 | C18: 단일감축사업 | D18: 덕산지에스의 부생연료유 2호에서 도시가스(LNG)로의 연료전환을 통한 온실가스 배출 감축사업 | E18: (주)덕산지에스 | F18: 2018-12-17~2028-12-16 | G18: 1차 (2018-12-17~2018-12-17) | H18: =VLOOKUP(D18,'인증실적 비공개승인관리_국내'!$D:$K,6,FALSE) -> 2022-05-16 | I18: =VLOOKUP(D18,'인증실적 비공개승인관리_국내'!$D:$K,7,FALSE) -> 산업통상부 | J18: =VLOOKUP(D18,'인증실적 비공개승인관리_국내'!$D:$K,8,FALSE) -> 2023-04-25 | K18: =VLOOKUP(A18,'인증실적 비공개승인관리_국내'!$A:$N,8,FALSE) -> 보완요청 | L18: =LEFT(G18,FIND("차",G18)) -> 1차 | M18: =MID(G18,FINDB("(",G18),10) -> 2018-12-17 | N18: =LEFT(VLOOKUP(D18,'국내인증(ORS)'!O:BI,38,0),10) -> 2022-05-16 | O18: =IF(N18=#REF!,"O","X") -> #REF! | P18: 검토필요 | Q18: 보완요청 | R18: 사업자 | S18: 보완요청 | T18: 사업자 | U18: 45012 | V18: 에코시안_조영우 | W18: 모니터링보고서 내용 중 비공개 필요 부분 정확히 명시 필요(모니터링보고서 증빙자료는 정보공개 대상 아님) | AE18: 내부방침
A19: =D19&L19&M19 -> 이연제약 진천공장의 B-C유에서 LNG로의 연료전환을 통한 온실가스 배출 감축사업1차2013-12-11 | B19: 17 | C19: 단일감축사업 | D19: 이연제약 진천공장의 B-C유에서 LNG로의 연료전환을 통한 온실가스 배출 감축사업 | E19: 이연제약(주) | F19: 2013-12-11~2023-12-10 | G19: 1차 (2013-12-11~2013-12-11) | H19: =VLOOKUP(D19,'인증실적 비공개승인관리_국내'!$D:$K,6,FALSE) -> 2022-02-15 | I19: =VLOOKUP(D19,'인증실적 비공개승인관리_국내'!$D:$K,7,FALSE) -> 산업통상부 | J19: =VLOOKUP(D19,'인증실적 비공개승인관리_국내'!$D:$K,8,FALSE) -> 2022-10-19 | K19: =VLOOKUP(A19,'인증실적 비공개승인관리_국내'!$A:$N,8,FALSE) -> 보완요청 | L19: =LEFT(G19,FIND("차",G19)) -> 1차 | M19: =MID(G19,FINDB("(",G19),10) -> 2013-12-11 | N19: =LEFT(VLOOKUP(D19,'국내인증(ORS)'!O:BI,38,0),10) -> 2024-09-06 | O19: =IF(N19=#REF!,"O","X") -> #REF! | P19: 검토필요 | Q19: 보완요청 | R19: 사업자 | S19: 보완요청 | T19: 사업자 | U19: 10월 13일 | V19: 에코시안 | W19: 모니터링보고서 및 검증보고서 내 보안유지 필요부분 구체화 필요 | AE19: 내부방침
A20: =D20&L20&M20 -> (주)선일로에스의 B-A유에서 LNG로 연료전환을 통한 온실가스 배출 감축사업1차2013-04-01 | B20: 18 | C20: 단일감축사업 | D20: (주)선일로에스의 B-A유에서 LNG로 연료전환을 통한 온실가스 배출 감축사업 | E20: (주)선일로에스 | F20: 2008-04-01~2018-03-31 | G20: 1차 (2013-04-01~2013-04-01) | H20: =VLOOKUP(D20,'인증실적 비공개승인관리_국내'!$D:$K,6,FALSE) -> 2022-01-04 | I20: =VLOOKUP(D20,'인증실적 비공개승인관리_국내'!$D:$K,7,FALSE) -> 산업통상부 | J20: =VLOOKUP(D20,'인증실적 비공개승인관리_국내'!$D:$K,8,FALSE) -> 2023-04-19 | K20: =VLOOKUP(A20,'인증실적 비공개승인관리_국내'!$A:$N,8,FALSE) -> 보완요청 | L20: =LEFT(G20,FIND("차",G20)) -> 1차 | M20: =MID(G20,FINDB("(",G20),10) -> 2013-04-01 | N20: =LEFT(VLOOKUP(D20,'국내인증(ORS)'!O:BI,38,0),10) -> 2022-01-04 | O20: =IF(N20=#REF!,"O","X") -> #REF! | P20: 검토필요 | Q20: 보완요청 | R20: 사업자 | S20: 보완요청 | T20: 사업자 | U20: 10월 13일 | V20: 에코시안 | W20: 모니터링보고서 및 검증보고서 내 보안유지 필요부분 구체화 필요 | AE20: 내부방침
A21: =D21&L21&M21 -> 금강 연료전환(B-C유->도시가스) 감축사업(C-002)1차2019-07-31 | B21: 19 | C21: 프로그램감축사업 | D21: 금강 연료전환(B-C유->도시가스) 감축사업(C-002) | E21: (주)삼천리 | F21: 2019-07-31~2026-07-30 | G21: 1차 (2019-07-31~2019-07-31) | H21: =VLOOKUP(D21,'인증실적 비공개승인관리_국내'!$D:$K,6,FALSE) -> 2021-12-22 | I21: =VLOOKUP(D21,'인증실적 비공개승인관리_국내'!$D:$K,7,FALSE) -> 산업통상부 | J21: =VLOOKUP(D21,'인증실적 비공개승인관리_국내'!$D:$K,8,FALSE) -> 2022-10-19 | K21: =VLOOKUP(A21,'인증실적 비공개승인관리_국내'!$A:$N,8,FALSE) -> 보완요청 | L21: =LEFT(G21,FIND("차",G21)) -> 1차 | M21: =MID(G21,FINDB("(",G21),10) -> 2019-07-31 | N21: =LEFT(VLOOKUP(D21,'국내인증(ORS)'!O:BI,38,0),10) -> 2021-12-17 | O21: =IF(N21=#REF!,"O","X") -> #REF! | P21: 검토필요 | Q21: 보완요청 | R21: 사업자 | S21: 보완요청 | T21: 사업자 | U21: 10월 13일 | V21: 에코시안 | W21: 모니터링보고서 및 검증보고서 내 보안유지 필요부분 구체화 필요(사유: 인증 실적 비공개) | AE21: 내부방침 | AF21: 사업명과 상이
A22: =D22&L22&M22 -> 부일레미콘의 B-C유에서 도시가스(LNG)로 연료전환을 통한 온실가스 배출 감축사업1차2018-01-25 | B22: 20 | C22: 단일감축사업 | D22: 부일레미콘의 B-C유에서 도시가스(LNG)로 연료전환을 통한 온실가스 배출 감축사업 | E22: (주)부일레미콘 | F22: 2018-01-25~2028-01-24 | G22: 1차 (2018-01-25~2018-01-25) | H22: =VLOOKUP(D22,'인증실적 비공개승인관리_국내'!$D:$K,6,FALSE) -> 2021-12-17 | I22: =VLOOKUP(D22,'인증실적 비공개승인관리_국내'!$D:$K,7,FALSE) -> 산업통상부 | J22: =VLOOKUP(D22,'인증실적 비공개승인관리_국내'!$D:$K,8,FALSE) -> 2022-10-19 | K22: =VLOOKUP(A22,'인증실적 비공개승인관리_국내'!$A:$N,8,FALSE) -> 보완요청 | L22: =LEFT(G22,FIND("차",G22)) -> 1차 | M22: =MID(G22,FINDB("(",G22),10) -> 2018-01-25 | N22: =LEFT(VLOOKUP(D22,'국내인증(ORS)'!O:BI,38,0),10) -> 2021-12-17 | O22: =IF(N22=#REF!,"O","X") -> #REF! | P22: 검토필요 | Q22: 보완요청 | R22: 사업자 | S22: 보완요청 | T22: 사업자 | U22: 10월 13일 | V22: 에코시안 | W22: 모니터링보고서 및 검증보고서 내 보안유지 필요부분 구체화 필요 | AE22: 내부방침
A23: =D23&L23&M23 -> 현대리바트의 부생연료 1호에서 LNG로 연료전환을 통한 온실가스 배출 감축사업1차2010-11-23 | B23: 21 | C23: 단일감축사업 | D23: 현대리바트의 부생연료 1호에서 LNG로 연료전환을 통한 온실가스 배출 감축사업 | E23: (주)현대리바트 | F23: 2010-11-23~2020-11-22 | G23: 1차 (2010-11-23~2010-11-23) | H23: =VLOOKUP(D23,'인증실적 비공개승인관리_국내'!$D:$K,6,FALSE) -> 2021-09-28 | I23: =VLOOKUP(D23,'인증실적 비공개승인관리_국내'!$D:$K,7,FALSE) -> 산업통상부 | J23: =VLOOKUP(D23,'인증실적 비공개승인관리_국내'!$D:$K,8,FALSE) -> 2022-10-19 | K23: =VLOOKUP(A23,'인증실적 비공개승인관리_국내'!$A:$N,8,FALSE) -> 보완요청 | L23: =LEFT(G23,FIND("차",G23)) -> 1차 | M23: =MID(G23,FINDB("(",G23),10) -> 2010-11-23 | N23: =LEFT(VLOOKUP(D23,'국내인증(ORS)'!O:BI,38,0),10) -> 2021-09-28 | O23: =IF(N23=#REF!,"O","X") -> #REF! | P23: 검토필요 | Q23: 보완요청 | R23: 사업자 | S23: 보완요청 | T23: 사업자 | U23: 10월 13일 | V23: 에코시안 | W23: 모니터링보고서 및 검증보고서 내 보안유지 필요부분 구체화 필요 | AE23: 내부방침
A24: =D24&L24&M24 -> 우성세라믹스공업의 LPG에서 LNG로 연료전환을 통한 온실가스 배출 감축사업1차2008-05-15 | B24: 22 | C24: 단일감축사업 | D24: 우성세라믹스공업의 LPG에서 LNG로 연료전환을 통한 온실가스 배출 감축사업 | E24: 우성세라믹스공업(주) | F24: 2008-05-15~2018-05-14 | G24: 1차 (2008-05-15~2008-05-15) | H24: =VLOOKUP(D24,'인증실적 비공개승인관리_국내'!$D:$K,6,FALSE) -> 2021-09-28 | I24: =VLOOKUP(D24,'인증실적 비공개승인관리_국내'!$D:$K,7,FALSE) -> 산업통상부 | J24: =VLOOKUP(D24,'인증실적 비공개승인관리_국내'!$D:$K,8,FALSE) -> 2022-06-03 | K24: =VLOOKUP(A24,'인증실적 비공개승인관리_국내'!$A:$N,8,FALSE) -> 보완요청 | L24: =LEFT(G24,FIND("차",G24)) -> 1차 | M24: =MID(G24,FINDB("(",G24),10) -> 2008-05-15 | N24: =LEFT(VLOOKUP(D24,'국내인증(ORS)'!O:BI,38,0),10) -> 2021-09-28 | O24: =IF(N24=#REF!,"O","X") -> #REF! | P24: 검토필요 | Q24: 보완요청 | R24: 사업자 | S24: 보완요청 | T24: 사업자 | U24: 5월 26일 | V24: 에코시안_조영우 | W24: 모니터링보고서 및 검증보고서 내 보안유지 필요부분 구체화 필요 | AE24: 내부방침
A25: =D25&L25&M25 -> 태형기업(주) 양주사업장의 B-C유에서 도시가스(LNG)로 연료전환을 통한 온실가스(CO2) 배출 감축사업1차2011-03-30 | B25: 23 | C25: 단일감축사업 | D25: 태형기업(주) 양주사업장의 B-C유에서 도시가스(LNG)로 연료전환을 통한 온실가스(CO2) 배출 감축사업 | E25: 태형기업(주) | F25: 2011-03-30~2021-03-29 | G25: 1차 (2011-03-30~2011-03-30) | H25: =VLOOKUP(D25,'인증실적 비공개승인관리_국내'!$D:$K,6,FALSE) -> 2021-04-22 | I25: =VLOOKUP(D25,'인증실적 비공개승인관리_국내'!$D:$K,7,FALSE) -> 산업통상부 | J25: =VLOOKUP(D25,'인증실적 비공개승인관리_국내'!$D:$K,8,FALSE) -> 2022-06-03 | K25: =VLOOKUP(A25,'인증실적 비공개승인관리_국내'!$A:$N,8,FALSE) -> 보완요청 | L25: =LEFT(G25,FIND("차",G25)) -> 1차 | M25: =MID(G25,FINDB("(",G25),10) -> 2011-03-30 | N25: =LEFT(VLOOKUP(D25,'국내인증(ORS)'!O:BI,38,0),10) -> 2021-04-22 | O25: =IF(N25=#REF!,"O","X") -> #REF! | P25: 검토필요 | Q25: 보완요청 | R25: 사업자 | S25: 보완요청 | T25: 사업자 | U25: 5월 26일 | V25: 에코시안_조영우 | W25: 모니터링보고서 및 검증보고서 내 보안유지 필요부분 구체화 필요 | AE25: 내부방침
